Workbook

Sheet Төсөл төлөвлөгөө биелэлт Нийгэм
U1: ТЭЗҮ Зураг төсл | V1: =+(G7*Q7+G9*Q9)/15% -> 0.60634885
B2: ТӨСЛИЙН ГҮЙЦЭТГЭЛ | U2: Барилга угсралт | V2: =+Q528 -> 0.23842289
B4: Д/Д | C4: Багцын дугаар | D4: Ажлын нэр | E4: Урьдчилсан төсөвт өртөг | F4: Хэсэгт эзлэх | G4: Төсөлд эзлэх хувь | H4: Төлөвлөгөөт хугацаа Гэрээ хавсралт 5 | J4: Төлөвлөгөөт хугацаа Гэрээ-Газар чөлөөлөлт хуулийн маргаан хассан Хавсралт 5 | L4: Бодит төлөвлөгөөт хугацаа Гүйцэтгэгч | N4: Төлөвлөгөөт хувь Гэрээ Хавсралт 5 | O4: Төлөвлөгөөт хувь Гэрээ-Газар чөлөөлөлт хуулийн маргаан хассан Хавсралт 5 | P4: Төлөвлөгөөт хувь Гүйцэтгэгч | Q4: Гүйцэтгэлийн хувь | R4: Төлөвлөгөө биелэлт Гэрээ | S4: Төлөвлөгөө биелэлт Гэрээ-Газар чөлөөлөлт хуулийн маргаан хассан | T4: Төлөвлөгөө биелэлт- Гүйцэтгэгч
H5: Эхлэх | I5: Дуусах | J5: Эхлэх | K5: Дуусах | L5: Эхлэх | M5: Дуусах
B6: ТӨСЛИЙН НИЙТ ГҮЙЦЭТГЭЛ | E6: =E7+E9+E528 -> 2.671905e+12 | G6: =+G7+G9+G83+G268+G342+G528+G904+G909 -> 1 | N6: =+$G7*N7+$G9*N9+$G83*N83+$G268*N268+$G342*N342+$G528*N528+$G904*N904+$G909*N909 -> 0.68721741 | O6: =+$G7*O7+$G9*O9+$G83*O83+$G268*O268+$G342*O342+$G528*O528+$G904*O904+$G909*O909 -> 0.61137166 | P6: =+$G7*P7+$G9*P9+$G83*P83+$G268*P268+$G342*P342+$G528*P528+$G904*P904+$G909*P909 -> 0.5773247 | Q6: =+$G7*Q7+$G9*Q9+$G83*Q83+$G268*Q268+$G342*Q342+$G528*Q528+$G904*Q904+$G909*Q909 -> 0.32246276 | R6: =+IF(N6=0,0,$Q6/N6) -> 0.46922961 | S6: =+IF(O6=0,0,$Q6/O6) -> 0.52744145 | T6: =+IF(P6=0,0,$Q6/P6) -> 0.55854661
B7: 1 | D7: ТЭЗҮ | E7: =E8 -> 3553800000 | G7: 0.05 | N7: =+($F8*N8) -> 1 | O7: =+($F8*O8) -> 1 | P7: =+($F8*P8) -> 1 | Q7: =+($F8*Q8) -> 1 | R7: =+IF(N7=0,0,$Q7/N7) -> 1 | S7: =+IF(O7=0,0,$Q7/O7) -> 1 | T7: =+IF(P7=0,0,$Q7/P7) -> 1
B8: 1.1 | C8: БАГЦ 1-6 БАГЦ 8-17 | D8: "Сэлбэ дэд төв" орчмын гэр хорооллыг дахин төлөвлөн орон сууцжуулах төслийн ТЭЗҮ, барилгажилтын төсөл, олон улсын зөвлөх үйлчилгээ, зураг төслийг боловсруулах ажил | E8: 3553800000 | F8: 1 | G8: =+F8*G7 -> 0.05 | H8: 45390 | I8: 45555 | J8: 45390 | K8: 45657 | L8: 45390 | M8: 45838 | N8: 1 | O8: 1 | P8: 1 | Q8: 1 | R8: =+IF(N8=0,0,$Q8/N8) -> 1 | S8: =+IF(O8=0,0,$Q8/O8) -> 1 | T8: =+IF(P8=0,0,$Q8/P8) -> 1
B9: 2 | D9: Ажлын зураг төсөл | E9: =E10+E61+E62+E70 -> 8220164289 | G9: 0.1 | N9: =+($F10*N10+$F61*N61+$F62*N62+$F70*N70) -> 0.99460003 | O9: =+($F10*O10+$F61*O61+$F62*O62+$F70*O70) -> 0.99460003 | P9: =+($F10*P10+$F61*P61+$F62*P62+$F70*P70) -> 0.99460003 | Q9: =+($F10*Q10+$F61*Q61+$F62*Q62) -> 0.40952328 | R9: =+IF(N9=0,0,$Q9/N9) -> 0.4117467 | S9: =+IF(O9=0,0,$Q9/O9) -> 0.4117467 | T9: =+IF(P9=0,0,$Q9/P9) -> 0.4117467
B10: 2.1 | C10: БАГЦ 1-6 БАГЦ 10-17 | D10: "Сэлбэ дэд төв" орчмын гэр хорооллыг дахин төлөвлөн орон сууцжуулах төслийн ТЭЗҮ, барилгажилтын төсөл, олон улсын зөвлөх үйлчилгээ, зураг төслийг боловсруулах ажил (Барилгажилты төсөл Хувилбар 2) нэмэлт ажил | E10: 533070000 | F10: =E10/$E$9 -> 0.064849069 | G10: =+F10*G9 -> 0.0064849069 | H10: 45768 | I10: 45884 | J10: 45768 | K10: 45884 | L10: 45768 | M10: 45884 | N10: =$F11*N11+$F19*N19+$F35*N35 -> 0.91673011 | O10: =$F11*O11+$F19*O19+$F35*O35 -> 0.91673011 | P10: =$F11*P11+$F19*P19+$F35*P35 -> 0.91673011 | Q10: =$F11*Q11+$F19*Q19+$F35*Q35 -> 0.91002471 | R10: =+IF(N10=0,0,$Q10/N10) -> 0.99268552 | S10: =+IF(O10=0,0,$Q10/O10) -> 0.99268552 | T10: =+IF(P10=0,0,$Q10/P10) -> 0.99268552
B11: 2.1.1 | C11: Багц- 1-4 | D11: Орон сууцны хороолол барилга угсралт | F11: =F719 -> 0.72937579 | G11: =+F11*G9 -> 0.072937579 | H11: 45768 | I11: 45884 | J11: 45768 | K11: 45884 | L11: 45768 | M11: 45884 | N11: =+$F12*N12+$F13*N13+$F14*N14+$F15*N15+$F16*N16+$F17*N17+$F18*N18 -> 1 | O11: =+$F12*O12+$F13*O13+$F14*O14+$F15*O15+$F16*O16+$F17*O17+$F18*O18 -> 1 | P11: =+$F12*P12+$F13*P13+$F14*P14+$F15*P15+$F16*P16+$F17*P17+$F18*P18 -> 1 | Q11: =+$F12*Q12+$F13*Q13+$F14*Q14+$F15*Q15+$F16*Q16+$F17*Q17+$F18*Q18 -> 1 | R11: =+IF(N11=0,0,$Q11/N11) -> 1 | S11: =+IF(O11=0,0,$Q11/O11) -> 1 | T11: =+IF(P11=0,0,$Q11/P11) -> 1
B12: 2.1.1 | C12: Багц-1 | D12: Орон сууцны хороолол барилга угсралт | F12: 0.20095297 | G12: =+F12*G11 -> 0.014657023 | H12: 45768 | I12: 45884 | J12: 45768 | K12: 45884 | L12: 45768 | M12: 45884 | N12: 1 | O12: 1 | P12: 1 | Q12: 1 | R12: =+IF(N12=0,0,$Q12/N12) -> 1 | S12: =+IF(O12=0,0,$Q12/O12) -> 1 | T12: =+IF(P12=0,0,$Q12/P12) -> 1
B13: 2.1.2 | C13: Багц-2 | D13: Орон сууцны хороолол барилга угсралт | F13: 0.24153553 | G13: =+F13*G11 -> 0.017617017 | H13: 45768 | I13: 45884 | J13: 45768 | K13: 45884 | L13: 45768 | M13: 45884 | N13: 1 | O13: 1 | P13: 1 | Q13: 1 | R13: =+IF(N13=0,0,$Q13/N13) -> 1 | S13: =+IF(O13=0,0,$Q13/O13) -> 1 | T13: =+IF(P13=0,0,$Q13/P13) -> 1
B14: 2.1.3 | C14: Багц-3.1 | D14: Орон сууцны хороолол барилга угсралт | F14: 0.094678015 | G14: =+F14*G11 -> 0.0069055852 | H14: 45768 | I14: 45884 | J14: 45768 | K14: 45884 | L14: 45768 | M14: 45884 | N14: 1 | O14: 1 | P14: 1 | Q14: 1 | R14: =+IF(N14=0,0,$Q14/N14) -> 1 | S14: =+IF(O14=0,0,$Q14/O14) -> 1 | T14: =+IF(P14=0,0,$Q14/P14) -> 1
B15: 2.1.4 | C15: Багц-3.2 | D15: Орон сууцны хороолол барилга угсралт | F15: 0.10115553 | G15: =+F15*G11 -> 0.0073780393 | H15: 45768 | I15: 45884 | J15: 45768 | K15: 45884 | L15: 45768 | M15: 45884 | N15: 1 | O15: 1 | P15: 1 | Q15: 1 | R15: =+IF(N15=0,0,$Q15/N15) -> 1 | S15: =+IF(O15=0,0,$Q15/O15) -> 1 | T15: =+IF(P15=0,0,$Q15/P15) -> 1
B16: 2.1.5 | C16: Багц-3.3 | D16: Орон сууцны хороолол барилга угсралт | F16: 0.11541079 | G16: =+F16*G11 -> 0.0084177839 | H16: 45768 | I16: 45884 | J16: 45768 | K16: 45884 | L16: 45768 | M16: 45884 | N16: 1 | O16: 1 | P16: 1 | Q16: 1 | R16: =+IF(N16=0,0,$Q16/N16) -> 1 | S16: =+IF(O16=0,0,$Q16/O16) -> 1 | T16: =+IF(P16=0,0,$Q16/P16) -> 1
B17: 2.1.6 | C17: Багц-4.1 | D17: Орон сууцны хороолол барилга угсралт | F17: 0.13984312 | G17: =+F17*G11 -> 0.010199819 | H17: 45768 | I17: 45884 | J17: 45768 | K17: 45884 | L17: 45768 | M17: 45884 | N17: 1 | O17: 1 | P17: 1 | Q17: 1 | R17: =+IF(N17=0,0,$Q17/N17) -> 1 | S17: =+IF(O17=0,0,$Q17/O17) -> 1 | T17: =+IF(P17=0,0,$Q17/P17) -> 1
B18: 2.1.7 | C18: Багц-4.2 | D18: Орон сууцны хороолол барилга угсралт | F18: 0.10642405 | G18: =+F18*G11 -> 0.0077623123 | H18: 45768 | I18: 45884 | J18: 45768 | K18: 45884 | L18: 45768 | M18: 45884 | N18: 1 | O18: 1 | P18: 1 | Q18: 1 | R18: =+IF(N18=0,0,$Q18/N18) -> 1 | S18: =+IF(O18=0,0,$Q18/O18) -> 1 | T18: =+IF(P18=0,0,$Q18/P18) -> 1
B19: 2.1.2 | C19: Багц-16, 17 | D19: ГАДНА ТОХИЖИЛТ, ӨНДӨРЖИЛТ | F19: =F842 -> 0.036449139 | G19: =+F19*G9 -> 0.0036449139 | H19: 45768 | I19: 45884 | J19: 45768 | K19: 45884 | N19: =+SUMPRODUCT($F20:$F34,N20:N34) -> 0.53129205 | O19: =+SUMPRODUCT($F20:$F34,O20:O34) -> 0.53129205 | P19: =+SUMPRODUCT($F20:$F34,P20:P34) -> 0.53129205 | Q19: =+SUMPRODUCT($F20:$F34,Q20:Q34) -> 0.90709062 | R19: =+IF(N19=0,0,$Q19/N19) -> 1.7073296 | S19: =+IF(O19=0,0,$Q19/O19) -> 1.7073296 | T19: =+IF(P19=0,0,$Q19/P19) -> 1.7073296
B20: 2.2.1 | C20: БАГЦ-16.1 | D20: Өндөржилтийн ажил БАГЦ 1 | F20: =F843 -> 0.092877611 | G20: =+F20*G19 -> 0.00033853089 | H20: 45768 | I20: 45884 | J20: 45768 | K20: 45884 | N20: 1 | O20: 1 | P20: 1 | Q20: 1 | R20: =+IF(N20=0,0,$Q20/N20) -> 1 | S20: =+IF(O20=0,0,$Q20/O20) -> 1 | T20: =+IF(P20=0,0,$Q20/P20) -> 1
B21: 2.2.2 | C21: БАГЦ-16.2 | D21: Өндөржилтийн ажил БАГЦ 2 | F21: =F844 -> 0.058105219 | G21: =+F21*G19 -> 0.00021178852 | H21: 45768 | I21: 45884 | J21: 45768 | K21: 45884 | N21: 1 | O21: 1 | P21: 1 | Q21: 1 | R21: =+IF(N21=0,0,$Q21/N21) -> 1 | S21: =+IF(O21=0,0,$Q21/O21) -> 1 | T21: =+IF(P21=0,0,$Q21/P21) -> 1
B22: 2.2.3 | C22: БАГЦ-16.3 | D22: Өндөржилтийн ажил БАГЦ 3.1 | F22: =F845 -> 0.027796911 | G22: =+F22*G19 -> 0.00010131735 | H22: 45768 | I22: 45884 | J22: 45768 | K22: 45884 | N22: 1 | O22: 1 | P22: 1 | Q22: 1 | R22: =+IF(N22=0,0,$Q22/N22) -> 1 | S22: =+IF(O22=0,0,$Q22/O22) -> 1 | T22: =+IF(P22=0,0,$Q22/P22) -> 1
B23: 2.2.4 | C23: БАГЦ-16.4 | D23: Өндөржилтийн ажил БАГЦ 3.2 | F23: =F846 -> 0.0291553 | G23: =+F23*G19 -> 0.00010626856 | H23: 45768 | I23: 45884 | J23: 45768 | K23: 45884 | N23: 1 | O23: 1 | P23: 1 | Q23: 1 | R23: =+IF(N23=0,0,$Q23/N23) -> 1 | S23: =+IF(O23=0,0,$Q23/O23) -> 1 | T23: =+IF(P23=0,0,$Q23/P23) -> 1
B24: 2.2.5 | C24: БАГЦ-16.5 | D24: Өндөржилтийн ажил БАГЦ 3.3 | F24: =F847 -> 0.040182802 | G24: =+F24*G19 -> 0.00014646285 | H24: 45768 | I24: 45884 | J24: 45768 | K24: 45884 | N24: 1 | O24: 1 | P24: 1 | Q24: 1 | R24: =+IF(N24=0,0,$Q24/N24) -> 1 | S24: =+IF(O24=0,0,$Q24/O24) -> 1 | T24: =+IF(P24=0,0,$Q24/P24) -> 1
B25: 2.2.6 | C25: БАГЦ-16.6 | D25: Өндөржилтийн ажил БАГЦ 4.1 | F25: =F848 -> 0.098615014 | G25: =+F25*G19 -> 0.00035944323 | H25: 45768 | I25: 45884 | J25: 45768 | K25: 45884 | N25: 1 | O25: 1 | P25: 1 | Q25: 1 | R25: =+IF(N25=0,0,$Q25/N25) -> 1 | S25: =+IF(O25=0,0,$Q25/O25) -> 1 | T25: =+IF(P25=0,0,$Q25/P25) -> 1
B26: 2.2.7 | C26: БАГЦ-16.7 | D26: Өндөржилтийн ажил БАГЦ 4.2 | F26: =F849 -> 0.091649809 | G26: =+F26*G19 -> 0.00033405566 | H26: 45768 | I26: 45884 | J26: 45768 | K26: 45884 | N26: 1 | O26: 1 | P26: 1 | Q26: 1 | R26: =+IF(N26=0,0,$Q26/N26) -> 1 | S26: =+IF(O26=0,0,$Q26/O26) -> 1 | T26: =+IF(P26=0,0,$Q26/P26) -> 1
B27: 2.2.8 | C27: БАГЦ-16.8 | D27: Өндөржилтийн ажил Олон нийтийн бүсийн ГИШС | F27: =F850 -> 0.092909381 | G27: =+F27*G19 -> 0.00033864669 | H27: 45768 | I27: 45884 | J27: 45768 | K27: 45884 | N27: 1 | O27: 1 | P27: 1 | Q27: 0 | R27: =+IF(N27=0,0,$Q27/N27) -> 0 | S27: =+IF(O27=0,0,$Q27/O27) -> 0 | T27: =+IF(P27=0,0,$Q27/P27) -> 0
B28: 2.2.9 | C28: БАГЦ-17.1 | D28: Гадна тохижилтийн ажил БАГЦ 1 | F28: =F851 -> 0.080887029 | G28: =+F28*G19 -> 0.00029482626 | H28: 45768 | I28: 45884 | J28: 45768 | K28: 45884 | Q28: 1 | R28: =+IF(N28=0,0,$Q28/N28) -> 0 | S28: =+IF(O28=0,0,$Q28/O28) -> 0 | T28: =+IF(P28=0,0,$Q28/P28) -> 0
B29: 2.2.10 | C29: БАГЦ-17.2 | D29: Гадна тохижилтийн ажил БАГЦ 2 | F29: =F852 -> 0.11788368 | G29: =+F29*G19 -> 0.00042967586 | H29: 45768 | I29: 45884 | J29: 45768 | K29: 45884 | Q29: 1 | R29: =+IF(N29=0,0,$Q29/N29) -> 0 | S29: =+IF(O29=0,0,$Q29/O29) -> 0 | T29: =+IF(P29=0,0,$Q29/P29) -> 0
B30: 2.2.11 | C30: БАГЦ-17.3 | D30: Гадна тохижилтийн ажил БАГЦ 3.1 | F30: =F853 -> 0.041046639 | G30: =+F30*G19 -> 0.00014961146 | H30: 45768 | I30: 45884 | J30: 45768 | K30: 45884 | Q30: 1 | R30: =+IF(N30=0,0,$Q30/N30) -> 0 | S30: =+IF(O30=0,0,$Q30/O30) -> 0 | T30: =+IF(P30=0,0,$Q30/P30) -> 0
B31: 2.2.12 | C31: БАГЦ-17.4 | D31: Гадна тохижилтийн ажил БАГЦ 3.2 | F31: =F854 -> 0.053741978 | G31: =+F31*G19 -> 0.00019588488 | H31: 45768 | I31: 45884 | J31: 45768 | K31: 45884 | Q31: 1 | R31: =+IF(N31=0,0,$Q31/N31) -> 0 | S31: =+IF(O31=0,0,$Q31/O31) -> 0 | T31: =+IF(P31=0,0,$Q31/P31) -> 0
B32: 2.2.13 | C32: БАГЦ-17.5 | D32: Гадна тохижилтийн ажил БАГЦ 3.3 | F32: =F855 -> 0.058057395 | G32: =+F32*G19 -> 0.0002116142 | H32: 45768 | I32: 45884 | J32: 45768 | K32: 45884 | Q32: 1 | R32: =+IF(N32=0,0,$Q32/N32) -> 0 | S32: =+IF(O32=0,0,$Q32/O32) -> 0 | T32: =+IF(P32=0,0,$Q32/P32) -> 0
B33: 2.2.14 | C33: БАГЦ-17.6 | D33: Гадна тохижилтийн ажил БАГЦ 4.1 | F33: =F856 -> 0.061612727 | G33: =+F33*G19 -> 0.00022457308 | H33: 45768 | I33: 45884 | J33: 45768 | K33: 45884 | Q33: 1 | R33: =+IF(N33=0,0,$Q33/N33) -> 0 | S33: =+IF(O33=0,0,$Q33/O33) -> 0 | T33: =+IF(P33=0,0,$Q33/P33) -> 0
B34: 2.2.15 | C34: БАГЦ-17.7 | D34: Гадна тохижилтийн ажил БАГЦ 4.2 | F34: =F857 -> 0.055478507 | G34: =+F34*G19 -> 0.00020221438 | H34: 45768 | I34: 45884 | J34: 45768 | K34: 45884 | Q34: 1 | R34: =+IF(N34=0,0,$Q34/N34) -> 0 | S34: =+IF(O34=0,0,$Q34/O34) -> 0 | T34: =+IF(P34=0,0,$Q34/P34) -> 0
B35: 2.1.3 | C35: Багц- 5,6 9-15 | D35: ИНЖЕНЕРИЙН ДЭД БҮТЭЦ | F35: =F858 -> 0.16798918 | G35: =+F35*G9 -> 0.016798918 | H35: 45768 | I35: 45884 | J35: 45768 | K35: 45884 | N35: =+$F36*N36+$F48*N48+$F56*N56 -> 1 | O35: =+$F36*O36+$F48*O48+$F56*O56 -> 1 | P35: =+$F36*P36+$F48*P48+$F56*P56 -> 1 | Q35: =+$F36*Q36+$F48*Q48+$F56*Q56 -> 0.87854613 | R35: =+IF(N35=0,0,$Q35/N35) -> 0.87854613 | S35: =+IF(O35=0,0,$Q35/O35) -> 0.87854613 | T35: =+IF(P35=0,0,$Q35/P35) -> 0.87854613
B36: 2.3.1 | C36: Багц 6 | D36: Гадна цахилгаан, холбоо дохиолол | F36: 0.5685609 | G36: =+F36*G35 -> 0.0095512081 | H36: 45768 | I36: 45884 | J36: 45768 | K36: 45884 | N36: =+SUMPRODUCT($F37:$F47,N37:N47) -> 1 | O36: =+SUMPRODUCT($F37:$F47,O37:O47) -> 1 | P36: =+SUMPRODUCT($F37:$F47,P37:P47) -> 1 | Q36: =+SUMPRODUCT($F37:$F47,Q37:Q47) -> 0.86016081 | R36: =+IF(N36=0,0,$Q36/N36) -> 0.86016081 | S36: =+IF(O36=0,0,$Q36/O36) -> 0.86016081 | T36: =+IF(P36=0,0,$Q36/P36) -> 0.86016081
B37: 2.3.1.1 | C37: Багц-6.1 | D37: Багц 1 Гадна цахилгаан, холбоо дохиолол | F37: 0.050651268 | G37: =+F37*G36 -> 0.0004837808 | H37: 45768 | I37: 45884 | J37: 45768 | K37: 45884 | N37: 1 | O37: 1 | P37: 1 | Q37: 1 | R37: =+IF(N37=0,0,$Q37/N37) -> 1 | S37: =+IF(O37=0,0,$Q37/O37) -> 1 | T37: =+IF(P37=0,0,$Q37/P37) -> 1
B38: 2.3.1.2 | C38: Багц-6.2 | D38: Багц 2 Гадна цахилгаан, холбоо дохиолол | F38: 0.082125454 | G38: =+F38*G36 -> 0.0007843973 | H38: 45768 | I38: 45884 | J38: 45768 | K38: 45884 | N38: 1 | O38: 1 | P38: 1 | Q38: 1 | R38: =+IF(N38=0,0,$Q38/N38) -> 1 | S38: =+IF(O38=0,0,$Q38/O38) -> 1 | T38: =+IF(P38=0,0,$Q38/P38) -> 1
B39: 2.3.1.3 | C39: Багц-6.3 | D39: Багц 3 Гадна цахилгаан, холбоо дохиолол | F39: 0.066964931 | G39: =+F39*G36 -> 0.00063959599 | H39: 45768 | I39: 45884 | J39: 45768 | K39: 45884 | N39: 1 | O39: 1 | P39: 1 | Q39: 1 | R39: =+IF(N39=0,0,$Q39/N39) -> 1 | S39: =+IF(O39=0,0,$Q39/O39) -> 1 | T39: =+IF(P39=0,0,$Q39/P39) -> 1
B40: 2.3.1.4 | C40: Багц-6.4 | D40: Багц 4 Гадна цахилгаан, холбоо дохиолол | F40: 0.082833365 | G40: =+F40*G36 -> 0.0007911587 | H40: 45768 | I40: 45884 | J40: 45768 | K40: 45884 | N40: 1 | O40: 1 | P40: 1 | Q40: 1 | R40: =+IF(N40=0,0,$Q40/N40) -> 1 | S40: =+IF(O40=0,0,$Q40/O40) -> 1 | T40: =+IF(P40=0,0,$Q40/P40) -> 1
B41: 2.3.1.5 | C41: Багц-6.5 | D41: "Сэлбэ дэд төв"-ийн барилгажилтын төслийн ХТП, РП-ний тоноглол, барилга угсралтын ажил (A хэсэг) | F41: 0.18485404 | G41: =+F41*G36 -> 0.0017655794 | H41: 45768 | I41: 45884 | J41: 45768 | K41: 45884 | N41: 1 | O41: 1 | P41: 1 | Q41: 1 | R41: =+IF(N41=0,0,$Q41/N41) -> 1 | S41: =+IF(O41=0,0,$Q41/O41) -> 1 | T41: =+IF(P41=0,0,$Q41/P41) -> 1
...

Sheet Төсөл төлөвлөгөө биелэлт сараар
B2: ТӨСЛИЙН ГҮЙЦЭТГЭЛ
B4: Д/Д | C4: Багцын дугаар | D4: Ажлын нэр | E4: Урьдчилсан төсөвт өртөг | F4: Хэсэгт эзлэх | G4: Төсөлд эзлэх хувь | H4: Гэрээ/Хавсралт 5 | J4: Гүйцэтгэгч | L4: ОСНАУГ/Газар чөлөөлөлт/ хуулийн маргаан/Өндөржилт нөлөөлөл | N4: 2026 он | S4: 2027 он | AE4: 2028 он
H5: Төлөвлөгөөт эхлэх | I5: Төлөвлөгөөт дуусах | J5: Төлөвлөгөөт эхлэх | K5: Төлөвлөгөөт дуусах | L5: Бодит Эхлэх | M5: Бодит дуусах | N5: 2026 он 8-р сар | O5: 2026 он 9-р сар | P5: 2026 он 10-р сар | Q5: 2026 он 11-р сар | R5: 2026 он 12-р сар | S5: 2027 он 1-р сар | T5: 2027 он 2-р сар | U5: 2027 он 3-р сар | V5: 2027 он 4-р сар | W5: 2027 он 5-р сар | X5: 2027 он 6-р сар | Y5: 2027 он 12-р сар | Z5: 2027 он 8-р сар | AA5: 2027 он 9-р сар | AB5: 2027 он 10-р сар | AC5: 2027 он 11-р сар | AD5: 2027 он 12-р сар | AE5: 2028 оны 1-р сар | AF5: 2028 оны 2-р сар | AG5: 2028 оны 3-р сар | AH5: 2028 оны 4-р сар | AI5: 2028 оны 5-р сар | AJ5: 2028 оны 6-р сар | AK5: 2028 оны 7-р сар | AL5: 2028 оны 8-р сар | AM5: 2028 оны 9-р сар | AN5: 2028 оны 10-р сар | AO5: 2028 оны 11-р сар | AP5: 2028 оны 12-р сар
B6: ТӨСЛИЙН НИЙТ ГҮЙЦЭТГЭЛ | E6: =E7+E9+E528 -> 2.4958419e+12 | G6: =+G7+G9+G83+G268+G342+G528+G904+G909 -> 1 | N6: =+$G7*N7+$G9*N9+$G83*N83+$G268*N268+$G342*N342+$G528*N528+$G904*N904+$G909*N909 -> 0.26425966 | O6: =+$G7*O7+$G9*O9+$G83*O83+$G268*O268+$G342*O342+$G528*O528+$G904*O904+$G909*O909 -> 0.36780664 | P6: =+$G7*P7+$G9*P9+$G83*P83+$G268*P268+$G342*P342+$G528*P528+$G904*P904+$G909*P909 -> 0.42935312 | Q6: =+$G7*Q7+$G9*Q9+$G83*Q83+$G268*Q268+$G342*Q342+$G528*Q528+$G904*Q904+$G909*Q909 -> 0.47631611 | R6: =+$G7*R7+$G9*R9+$G83*R83+$G268*R268+$G342*R342+$G528*R528+$G904*R904+$G909*R909 -> 0.51925877 | S6: =+$G7*S7+$G9*S9+$G83*S83+$G268*S268+$G342*S342+$G528*S528+$G904*S904+$G909*S909 -> 0.56015026 | T6: =+$G7*T7+$G9*T9+$G83*T83+$G268*T268+$G342*T342+$G528*T528+$G904*T904+$G909*T909 -> 0.5784518 | U6: =+$G7*U7+$G9*U9+$G83*U83+$G268*U268+$G342*U342+$G528*U528+$G904*U904+$G909*U909 -> 0.60422566 | ... AP6: =+$G7*AP7+$G9*AP9+$G83*AP83+$G268*AP268+$G342*AP342+$G528*AP528+$G904*AP904+$G909*AP909 -> 0.89909606
B7: 1 | D7: ТЭЗҮ | E7: =E8 -> 3553800000 | G7: 0.05 | H7: 45390 | I7: 45555 | N7: =+($F8*N8) -> 1 | O7: =+($F8*O8) -> 1 | P7: =+($F8*P8) -> 1 | Q7: =+($F8*Q8) -> 1 | R7: =+($F8*R8) -> 1 | S7: =+($F8*S8) -> 1 | T7: =+($F8*T8) -> 1 | U7: =+($F8*U8) -> 1 | ... AP7: =+($F8*AP8) -> 1
B8: 1.1 | C8: БАГЦ 1-6 БАГЦ 8-17 | D8: "Сэлбэ дэд төв" орчмын гэр хорооллыг дахин төлөвлөн орон сууцжуулах төслийн ТЭЗҮ, барилгажилтын төсөл, олон улсын зөвлөх үйлчилгээ, зураг төслийг боловсруулах ажил | E8: 3553800000 | F8: 1 | G8: =+F8*G7 -> 0.05 | N8: 1 | O8: 1 | P8: 1 | Q8: 1 | R8: 1 | S8: 1 | T8: 1 | U8: 1 | V8: 1 | W8: 1 | X8: 1 | Y8: 1 | Z8: 1 | AA8: 1 | AB8: 1 | AC8: 1 | AD8: 1 | AE8: 1 | AF8: 1 | AG8: 1 | AH8: 1 | AI8: 1 | AJ8: 1 | AK8: 1 | AL8: 1 | AM8: 1 | AN8: 1 | AO8: 1 | AP8: 1
B9: 2 | D9: Ажлын зураг төсөл | E9: =E10+E61+E62 -> 8220164289 | G9: 0.1 | H9: 45390 | I9: 45884 | N9: =($F10*N10+$F61*N61+$F62*N62+$F70*N70) -> 0.92023451 | O9: =($F10*O10+$F61*O61+$F62*O62+$F70*O70) -> 0.92023451 | P9: =($F10*P10+$F61*P61+$F62*P62+$F70*P70) -> 0.92023451 | Q9: =($F10*Q10+$F61*Q61+$F62*Q62+$F70*Q70) -> 0.92023451 | R9: =($F10*R10+$F61*R61+$F62*R62+$F70*R70) -> 0.92023451 | S9: =($F10*S10+$F61*S61+$F62*S62+$F70*S70) -> 0.92023451 | T9: =($F10*T10+$F61*T61+$F62*T62+$F70*T70) -> 0.92023451 | U9: =($F10*U10+$F61*U61+$F62*U62+$F70*U70) -> 0.92023451 | ... AP9: =($F10*AP10+$F61*AP61+$F62*AP62+$F70*AP70) -> 0.92023451
B10: 2.1 | C10: БАГЦ 1-6 БАГЦ 10-17 | D10: "Сэлбэ дэд төв" орчмын гэр хорооллыг дахин төлөвлөн орон сууцжуулах төслийн ТЭЗҮ, барилгажилтын төсөл, олон улсын зөвлөх үйлчилгээ, зураг төслийг боловсруулах ажил (Барилгажилты төсөл Хувилбар 2) нэмэлт ажил | E10: 533070000 | F10: 0.666 | G10: =+F10*G9 -> 0.0666 | N10: =$F11*N11+$F19*N19+$F35*N35 -> 0.97452448 | O10: =$F11*O11+$F19*O19+$F35*O35 -> 0.97452448 | P10: =$F11*P11+$F19*P19+$F35*P35 -> 0.97452448 | Q10: =$F11*Q11+$F19*Q19+$F35*Q35 -> 0.97452448 | R10: =$F11*R11+$F19*R19+$F35*R35 -> 0.97452448 | S10: =$F11*S11+$F19*S19+$F35*S35 -> 0.97452448 | T10: =$F11*T11+$F19*T19+$F35*T35 -> 0.97452448 | U10: =$F11*U11+$F19*U19+$F35*U35 -> 0.97452448 | ... AP10: =$F11*AP11+$F19*AP19+$F35*AP35 -> 0.97452448
B11: 2.1.1 | C11: Багц- 1-4 | D11: Орон сууцны хороолол барилга угсралт | F11: =F719 -> 0.78107172 | G11: =+F11*G9 -> 0.078107172 | N11: =+$F12*N12+$F13*N13+$F14*N14+$F15*N15+$F16*N16+$F17*N17+$F18*N18 -> 1 | O11: =+$F12*O12+$F13*O13+$F14*O14+$F15*O15+$F16*O16+$F17*O17+$F18*O18 -> 1 | P11: =+$F12*P12+$F13*P13+$F14*P14+$F15*P15+$F16*P16+$F17*P17+$F18*P18 -> 1 | Q11: =+$F12*Q12+$F13*Q13+$F14*Q14+$F15*Q15+$F16*Q16+$F17*Q17+$F18*Q18 -> 1 | R11: =+$F12*R12+$F13*R13+$F14*R14+$F15*R15+$F16*R16+$F17*R17+$F18*R18 -> 1 | S11: =+$F12*S12+$F13*S13+$F14*S14+$F15*S15+$F16*S16+$F17*S17+$F18*S18 -> 1 | T11: =+$F12*T12+$F13*T13+$F14*T14+$F15*T15+$F16*T16+$F17*T17+$F18*T18 -> 1 | U11: =+$F12*U12+$F13*U13+$F14*U14+$F15*U15+$F16*U16+$F17*U17+$F18*U18 -> 1 | ... AP11: =+$F12*AP12+$F13*AP13+$F14*AP14+$F15*AP15+$F16*AP16+$F17*AP17+$F18*AP18 -> 1
B12: 2.1.1 | C12: Багц-1 | D12: Орон сууцны хороолол барилга угсралт | F12: 0.20095297 | G12: =+F12*G11 -> 0.015695868 | N12: 1 | O12: 1 | P12: 1 | Q12: 1 | R12: 1 | S12: 1 | T12: 1 | U12: 1 | V12: 1 | W12: 1 | X12: 1 | Y12: 1 | Z12: 1 | AA12: 1 | AB12: 1 | AC12: 1 | AD12: 1 | AE12: 1 | AF12: 1 | AG12: 1 | AH12: 1 | AI12: 1 | AJ12: 1 | AK12: 1 | AL12: 1 | AM12: 1 | AN12: 1 | AO12: 1 | AP12: 1
B13: 2.1.2 | C13: Багц-2 | D13: Орон сууцны хороолол барилга угсралт | F13: 0.24153553 | G13: =+F13*G11 -> 0.018865657 | N13: 1 | O13: 1 | P13: 1 | Q13: 1 | R13: 1 | S13: 1 | T13: 1 | U13: 1 | V13: 1 | W13: 1 | X13: 1 | Y13: 1 | Z13: 1 | AA13: 1 | AB13: 1 | AC13: 1 | AD13: 1 | AE13: 1 | AF13: 1 | AG13: 1 | AH13: 1 | AI13: 1 | AJ13: 1 | AK13: 1 | AL13: 1 | AM13: 1 | AN13: 1 | AO13: 1 | AP13: 1
B14: 2.1.3 | C14: Багц-3.1 | D14: Орон сууцны хороолол барилга угсралт | F14: 0.094678015 | G14: =+F14*G11 -> 0.007395032 | N14: 1 | O14: 1 | P14: 1 | Q14: 1 | R14: 1 | S14: 1 | T14: 1 | U14: 1 | V14: 1 | W14: 1 | X14: 1 | Y14: 1 | Z14: 1 | AA14: 1 | AB14: 1 | AC14: 1 | AD14: 1 | AE14: 1 | AF14: 1 | AG14: 1 | AH14: 1 | AI14: 1 | AJ14: 1 | AK14: 1 | AL14: 1 | AM14: 1 | AN14: 1 | AO14: 1 | AP14: 1
B15: 2.1.4 | C15: Багц-3.2 | D15: Орон сууцны хороолол барилга угсралт | F15: 0.10115553 | G15: =+F15*G11 -> 0.0079009722 | N15: 1 | O15: 1 | P15: 1 | Q15: 1 | R15: 1 | S15: 1 | T15: 1 | U15: 1 | V15: 1 | W15: 1 | X15: 1 | Y15: 1 | Z15: 1 | AA15: 1 | AB15: 1 | AC15: 1 | AD15: 1 | AE15: 1 | AF15: 1 | AG15: 1 | AH15: 1 | AI15: 1 | AJ15: 1 | AK15: 1 | AL15: 1 | AM15: 1 | AN15: 1 | AO15: 1 | AP15: 1
B16: 2.1.5 | C16: Багц-3.3 | D16: Орон сууцны хороолол барилга угсралт | F16: 0.11541079 | G16: =+F16*G11 -> 0.0090144107 | N16: 1 | O16: 1 | P16: 1 | Q16: 1 | R16: 1 | S16: 1 | T16: 1 | U16: 1 | V16: 1 | W16: 1 | X16: 1 | Y16: 1 | Z16: 1 | AA16: 1 | AB16: 1 | AC16: 1 | AD16: 1 | AE16: 1 | AF16: 1 | AG16: 1 | AH16: 1 | AI16: 1 | AJ16: 1 | AK16: 1 | AL16: 1 | AM16: 1 | AN16: 1 | AO16: 1 | AP16: 1
B17: 2.1.6 | C17: Багц-4.1 | D17: Орон сууцны хороолол барилга угсралт | F17: 0.13984312 | G17: =+F17*G11 -> 0.010922751 | N17: 1 | O17: 1 | P17: 1 | Q17: 1 | R17: 1 | S17: 1 | T17: 1 | U17: 1 | V17: 1 | W17: 1 | X17: 1 | Y17: 1 | Z17: 1 | AA17: 1 | AB17: 1 | AC17: 1 | AD17: 1 | AE17: 1 | AF17: 1 | AG17: 1 | AH17: 1 | AI17: 1 | AJ17: 1 | AK17: 1 | AL17: 1 | AM17: 1 | AN17: 1 | AO17: 1 | AP17: 1
B18: 2.1.7 | C18: Багц-4.2 | D18: Орон сууцны хороолол барилга угсралт | F18: 0.10642405 | G18: =+F18*G11 -> 0.0083124812 | N18: 1 | O18: 1 | P18: 1 | Q18: 1 | R18: 1 | S18: 1 | T18: 1 | U18: 1 | V18: 1 | W18: 1 | X18: 1 | Y18: 1 | Z18: 1 | AA18: 1 | AB18: 1 | AC18: 1 | AD18: 1 | AE18: 1 | AF18: 1 | AG18: 1 | AH18: 1 | AI18: 1 | AJ18: 1 | AK18: 1 | AL18: 1 | AM18: 1 | AN18: 1 | AO18: 1 | AP18: 1
B19: 2.1.2 | C19: Багц-16, 17 | D19: ГАДНА ТОХИЖИЛТ, ӨНДӨРЖИЛТ | F19: =F842 -> 0.039032542 | G19: =+F19*G9 -> 0.0039032542 | N19: =+SUMPRODUCT($F20:$F34,N20:N34) -> 0.90709062 | O19: =+SUMPRODUCT($F20:$F34,O20:O34) -> 0.90709062 | P19: =+SUMPRODUCT($F20:$F34,P20:P34) -> 0.90709062 | Q19: =+SUMPRODUCT($F20:$F34,Q20:Q34) -> 0.90709062 | R19: =+SUMPRODUCT($F20:$F34,R20:R34) -> 0.90709062 | S19: =+SUMPRODUCT($F20:$F34,S20:S34) -> 0.90709062 | T19: =+SUMPRODUCT($F20:$F34,T20:T34) -> 0.90709062 | U19: =+SUMPRODUCT($F20:$F34,U20:U34) -> 0.90709062 | ... AP19: =+SUMPRODUCT($F20:$F34,AP20:AP34) -> 0.90709062
B20: 2.2.1 | C20: БАГЦ-16.1 | D20: Өндөржилтийн ажил БАГЦ 1 | F20: =F843 -> 0.092877611 | G20: =+F20*G19 -> 0.00036252493 | N20: 1 | O20: 1 | P20: 1 | Q20: 1 | R20: 1 | S20: 1 | T20: 1 | U20: 1 | V20: 1 | W20: 1 | X20: 1 | Y20: 1 | Z20: 1 | AA20: 1 | AB20: 1 | AC20: 1 | AD20: 1 | AE20: 1 | AF20: 1 | AG20: 1 | AH20: 1 | AI20: 1 | AJ20: 1 | AK20: 1 | AL20: 1 | AM20: 1 | AN20: 1 | AO20: 1 | AP20: 1
B21: 2.2.2 | C21: БАГЦ-16.2 | D21: Өндөржилтийн ажил БАГЦ 2 | F21: =F844 -> 0.058105219 | G21: =+F21*G19 -> 0.00022679944 | N21: 1 | O21: 1 | P21: 1 | Q21: 1 | R21: 1 | S21: 1 | T21: 1 | U21: 1 | V21: 1 | W21: 1 | X21: 1 | Y21: 1 | Z21: 1 | AA21: 1 | AB21: 1 | AC21: 1 | AD21: 1 | AE21: 1 | AF21: 1 | AG21: 1 | AH21: 1 | AI21: 1 | AJ21: 1 | AK21: 1 | AL21: 1 | AM21: 1 | AN21: 1 | AO21: 1 | AP21: 1
B22: 2.2.3 | C22: БАГЦ-16.3 | D22: Өндөржилтийн ажил БАГЦ 3.1 | F22: =F845 -> 0.027796911 | G22: =+F22*G19 -> 0.00010849841 | N22: 1 | O22: 1 | P22: 1 | Q22: 1 | R22: 1 | S22: 1 | T22: 1 | U22: 1 | V22: 1 | W22: 1 | X22: 1 | Y22: 1 | Z22: 1 | AA22: 1 | AB22: 1 | AC22: 1 | AD22: 1 | AE22: 1 | AF22: 1 | AG22: 1 | AH22: 1 | AI22: 1 | AJ22: 1 | AK22: 1 | AL22: 1 | AM22: 1 | AN22: 1 | AO22: 1 | AP22: 1
B23: 2.2.4 | C23: БАГЦ-16.4 | D23: Өндөржилтийн ажил БАГЦ 3.2 | F23: =F846 -> 0.0291553 | G23: =+F23*G19 -> 0.00011380055 | N23: 1 | O23: 1 | P23: 1 | Q23: 1 | R23: 1 | S23: 1 | T23: 1 | U23: 1 | V23: 1 | W23: 1 | X23: 1 | Y23: 1 | Z23: 1 | AA23: 1 | AB23: 1 | AC23: 1 | AD23: 1 | AE23: 1 | AF23: 1 | AG23: 1 | AH23: 1 | AI23: 1 | AJ23: 1 | AK23: 1 | AL23: 1 | AM23: 1 | AN23: 1 | AO23: 1 | AP23: 1
B24: 2.2.5 | C24: БАГЦ-16.5 | D24: Өндөржилтийн ажил БАГЦ 3.3 | F24: =F847 -> 0.040182802 | G24: =+F24*G19 -> 0.00015684369 | N24: 1 | O24: 1 | P24: 1 | Q24: 1 | R24: 1 | S24: 1 | T24: 1 | U24: 1 | V24: 1 | W24: 1 | X24: 1 | Y24: 1 | Z24: 1 | AA24: 1 | AB24: 1 | AC24: 1 | AD24: 1 | AE24: 1 | AF24: 1 | AG24: 1 | AH24: 1 | AI24: 1 | AJ24: 1 | AK24: 1 | AL24: 1 | AM24: 1 | AN24: 1 | AO24: 1 | AP24: 1
B25: 2.2.6 | C25: БАГЦ-16.6 | D25: Өндөржилтийн ажил БАГЦ 4.1 | F25: =F848 -> 0.098615014 | G25: =+F25*G19 -> 0.00038491947 | N25: 1 | O25: 1 | P25: 1 | Q25: 1 | R25: 1 | S25: 1 | T25: 1 | U25: 1 | V25: 1 | W25: 1 | X25: 1 | Y25: 1 | Z25: 1 | AA25: 1 | AB25: 1 | AC25: 1 | AD25: 1 | AE25: 1 | AF25: 1 | AG25: 1 | AH25: 1 | AI25: 1 | AJ25: 1 | AK25: 1 | AL25: 1 | AM25: 1 | AN25: 1 | AO25: 1 | AP25: 1
B26: 2.2.7 | C26: БАГЦ-16.7 | D26: Өндөржилтийн ажил БАГЦ 4.2 | F26: =F849 -> 0.091649809 | G26: =+F26*G19 -> 0.00035773251 | N26: 1 | O26: 1 | P26: 1 | Q26: 1 | R26: 1 | S26: 1 | T26: 1 | U26: 1 | V26: 1 | W26: 1 | X26: 1 | Y26: 1 | Z26: 1 | AA26: 1 | AB26: 1 | AC26: 1 | AD26: 1 | AE26: 1 | AF26: 1 | AG26: 1 | AH26: 1 | AI26: 1 | AJ26: 1 | AK26: 1 | AL26: 1 | AM26: 1 | AN26: 1 | AO26: 1 | AP26: 1
B27: 2.2.8 | C27: БАГЦ-16.8 | D27: Өндөржилтийн ажил Олон нийтийн бүсийн ГИШС | F27: =F850 -> 0.092909381 | G27: =+F27*G19 -> 0.00036264893 | N27: 0 | O27: 0 | P27: 0 | Q27: 0 | R27: 0 | S27: 0 | T27: 0 | U27: 0 | V27: 0 | W27: 0 | X27: 0 | Y27: 0 | Z27: 0 | AA27: 0 | AB27: 0 | AC27: 0 | AD27: 0 | AE27: 0 | AF27: 0
B28: 2.2.9 | C28: БАГЦ-17.1 | D28: Гадна тохижилтийн ажил БАГЦ 1 | F28: =F851 -> 0.080887029 | G28: =+F28*G19 -> 0.00031572264 | N28: 1 | O28: 1 | P28: 1 | Q28: 1 | R28: 1 | S28: 1 | T28: 1 | U28: 1 | V28: 1 | W28: 1 | X28: 1 | Y28: 1 | Z28: 1 | AA28: 1 | AB28: 1 | AC28: 1 | AD28: 1 | AE28: 1 | AF28: 1 | AG28: 1 | AH28: 1 | AI28: 1 | AJ28: 1 | AK28: 1 | AL28: 1 | AM28: 1 | AN28: 1 | AO28: 1 | AP28: 1
B29: 2.2.10 | C29: БАГЦ-17.2 | D29: Гадна тохижилтийн ажил БАГЦ 2 | F29: =F852 -> 0.11788368 | G29: =+F29*G19 -> 0.00046012997 | N29: 1 | O29: 1 | P29: 1 | Q29: 1 | R29: 1 | S29: 1 | T29: 1 | U29: 1 | V29: 1 | W29: 1 | X29: 1 | Y29: 1 | Z29: 1 | AA29: 1 | AB29: 1 | AC29: 1 | AD29: 1 | AE29: 1 | AF29: 1 | AG29: 1 | AH29: 1 | AI29: 1 | AJ29: 1 | AK29: 1 | AL29: 1 | AM29: 1 | AN29: 1 | AO29: 1 | AP29: 1
B30: 2.2.11 | C30: БАГЦ-17.3 | D30: Гадна тохижилтийн ажил БАГЦ 3.1 | F30: =F853 -> 0.041046639 | G30: =+F30*G19 -> 0.00016021547 | N30: 1 | O30: 1 | P30: 1 | Q30: 1 | R30: 1 | S30: 1 | T30: 1 | U30: 1 | V30: 1 | W30: 1 | X30: 1 | Y30: 1 | Z30: 1 | AA30: 1 | AB30: 1 | AC30: 1 | AD30: 1 | AE30: 1 | AF30: 1 | AG30: 1 | AH30: 1 | AI30: 1 | AJ30: 1 | AK30: 1 | AL30: 1 | AM30: 1 | AN30: 1 | AO30: 1 | AP30: 1
B31: 2.2.12 | C31: БАГЦ-17.4 | D31: Гадна тохижилтийн ажил БАГЦ 3.2 | F31: =F854 -> 0.053741978 | G31: =+F31*G19 -> 0.0002097686 | N31: 1 | O31: 1 | P31: 1 | Q31: 1 | R31: 1 | S31: 1 | T31: 1 | U31: 1 | V31: 1 | W31: 1 | X31: 1 | Y31: 1 | Z31: 1 | AA31: 1 | AB31: 1 | AC31: 1 | AD31: 1 | AE31: 1 | AF31: 1 | AG31: 1 | AH31: 1 | AI31: 1 | AJ31: 1 | AK31: 1 | AL31: 1 | AM31: 1 | AN31: 1 | AO31: 1 | AP31: 1
B32: 2.2.13 | C32: БАГЦ-17.5 | D32: Гадна тохижилтийн ажил БАГЦ 3.3 | F32: =F855 -> 0.058057395 | G32: =+F32*G19 -> 0.00022661277 | N32: 1 | O32: 1 | P32: 1 | Q32: 1 | R32: 1 | S32: 1 | T32: 1 | U32: 1 | V32: 1 | W32: 1 | X32: 1 | Y32: 1 | Z32: 1 | AA32: 1 | AB32: 1 | AC32: 1 | AD32: 1 | AE32: 1 | AF32: 1 | AG32: 1 | AH32: 1 | AI32: 1 | AJ32: 1 | AK32: 1 | AL32: 1 | AM32: 1 | AN32: 1 | AO32: 1 | AP32: 1
B33: 2.2.14 | C33: БАГЦ-17.6 | D33: Гадна тохижилтийн ажил БАГЦ 4.1 | F33: =F856 -> 0.061612727 | G33: =+F33*G19 -> 0.00024049014 | N33: 1 | O33: 1 | P33: 1 | Q33: 1 | R33: 1 | S33: 1 | T33: 1 | U33: 1 | V33: 1 | W33: 1 | X33: 1 | Y33: 1 | Z33: 1 | AA33: 1 | AB33: 1 | AC33: 1 | AD33: 1 | AE33: 1 | AF33: 1 | AG33: 1 | AH33: 1 | AI33: 1 | AJ33: 1 | AK33: 1 | AL33: 1 | AM33: 1 | AN33: 1 | AO33: 1 | AP33: 1
B34: 2.2.15 | C34: БАГЦ-17.7 | D34: Гадна тохижилтийн ажил БАГЦ 4.2 | F34: =F857 -> 0.055478507 | G34: =+F34*G19 -> 0.00021654672 | N34: 1 | O34: 1 | P34: 1 | Q34: 1 | R34: 1 | S34: 1 | T34: 1 | U34: 1 | V34: 1 | W34: 1 | X34: 1 | Y34: 1 | Z34: 1 | AA34: 1 | AB34: 1 | AC34: 1 | AD34: 1 | AE34: 1 | AF34: 1 | AG34: 1 | AH34: 1 | AI34: 1 | AJ34: 1 | AK34: 1 | AL34: 1 | AM34: 1 | AN34: 1 | AO34: 1 | AP34: 1
B35: 2.1.3 | C35: Багц- 5,6 9-15 | D35: ИНЖЕНЕРИЙН ДЭД БҮТЭЦ | F35: =F858 -> 0.17989574 | G35: =+F35*G9 -> 0.017989574 | N35: =+$F36*N36+$F48*N48+$F56*N56 -> 0.87854613 | O35: =+$F36*O36+$F48*O48+$F56*O56 -> 0.87854613 | P35: =+$F36*P36+$F48*P48+$F56*P56 -> 0.87854613 | Q35: =+$F36*Q36+$F48*Q48+$F56*Q56 -> 0.87854613 | R35: =+$F36*R36+$F48*R48+$F56*R56 -> 0.87854613 | S35: =+$F36*S36+$F48*S48+$F56*S56 -> 0.87854613 | T35: =+$F36*T36+$F48*T48+$F56*T56 -> 0.87854613 | U35: =+$F36*U36+$F48*U48+$F56*U56 -> 0.87854613 | ... AP35: =+$F36*AP36+$F48*AP48+$F56*AP56 -> 0.87854613
B36: 2.3.1 | C36: Багц 6 | D36: Гадна цахилгаан, холбоо дохиолол | F36: 0.5685609 | G36: =+F36*G35 -> 0.010228168 | N36: =+SUMPRODUCT($F37:$F47,N37:N47) -> 0.86016081 | O36: =+SUMPRODUCT($F37:$F47,O37:O47) -> 0.86016081 | P36: =+SUMPRODUCT($F37:$F47,P37:P47) -> 0.86016081 | Q36: =+SUMPRODUCT($F37:$F47,Q37:Q47) -> 0.86016081 | R36: =+SUMPRODUCT($F37:$F47,R37:R47) -> 0.86016081 | S36: =+SUMPRODUCT($F37:$F47,S37:S47) -> 0.86016081 | T36: =+SUMPRODUCT($F37:$F47,T37:T47) -> 0.86016081 | U36: =+SUMPRODUCT($F37:$F47,U37:U47) -> 0.86016081 | ... AP36: =+SUMPRODUCT($F37:$F47,AP37:AP47) -> 0.86016081
B37: 2.3.1.1 | C37: Багц-6.1 | D37: Багц 1 Гадна цахилгаан, холбоо дохиолол | F37: 0.050651268 | G37: =+F37*G36 -> 0.0005180697 | N37: 1 | O37: 1 | P37: 1 | Q37: 1 | R37: 1 | S37: 1 | T37: 1 | U37: 1 | V37: 1 | W37: 1 | X37: 1 | Y37: 1 | Z37: 1 | AA37: 1 | AB37: 1 | AC37: 1 | AD37: 1 | AE37: 1 | AF37: 1 | AG37: 1 | AH37: 1 | AI37: 1 | AJ37: 1 | AK37: 1 | AL37: 1 | AM37: 1 | AN37: 1 | AO37: 1 | AP37: 1
B38: 2.3.1.2 | C38: Багц-6.2 | D38: Багц 2 Гадна цахилгаан, холбоо дохиолол | F38: 0.082125454 | G38: =+F38*G36 -> 0.00083999298 | N38: 1 | O38: 1 | P38: 1 | Q38: 1 | R38: 1 | S38: 1 | T38: 1 | U38: 1 | V38: 1 | W38: 1 | X38: 1 | Y38: 1 | Z38: 1 | AA38: 1 | AB38: 1 | AC38: 1 | AD38: 1 | AE38: 1 | AF38: 1 | AG38: 1 | AH38: 1 | AI38: 1 | AJ38: 1 | AK38: 1 | AL38: 1 | AM38: 1 | AN38: 1 | AO38: 1 | AP38: 1
B39: 2.3.1.3 | C39: Багц-6.3 | D39: Багц 3 Гадна цахилгаан, холбоо дохиолол | F39: 0.066964931 | G39: =+F39*G36 -> 0.0006849286 | N39: 1 | O39: 1 | P39: 1 | Q39: 1 | R39: 1 | S39: 1 | T39: 1 | U39: 1 | V39: 1 | W39: 1 | X39: 1 | Y39: 1 | Z39: 1 | AA39: 1 | AB39: 1 | AC39: 1 | AD39: 1 | AE39: 1 | AF39: 1 | AG39: 1 | AH39: 1 | AI39: 1 | AJ39: 1 | AK39: 1 | AL39: 1 | AM39: 1 | AN39: 1 | AO39: 1 | AP39: 1
B40: 2.3.1.4 | C40: Багц-6.4 | D40: Багц 4 Гадна цахилгаан, холбоо дохиолол | F40: 0.082833365 | G40: =+F40*G36 -> 0.00084723361 | N40: 1 | O40: 1 | P40: 1 | Q40: 1 | R40: 1 | S40: 1 | T40: 1 | U40: 1 | V40: 1 | W40: 1 | X40: 1 | Y40: 1 | Z40: 1 | AA40: 1 | AB40: 1 | AC40: 1 | AD40: 1 | AE40: 1 | AF40: 1 | AG40: 1 | AH40: 1 | AI40: 1 | AJ40: 1 | AK40: 1 | AL40: 1 | AM40: 1 | AN40: 1 | AO40: 1 | AP40: 1
B41: 2.3.1.5 | C41: Багц-6.5 | D41: "Сэлбэ дэд төв"-ийн барилгажилтын төслийн ХТП, РП-ний тоноглол, барилга угсралтын ажил (A хэсэг) | F41: 0.18485404 | G41: =+F41*G36 -> 0.0018907182 | N41: 1 | O41: 1 | P41: 1 | Q41: 1 | R41: 1 | S41: 1 | T41: 1 | U41: 1 | V41: 1 | W41: 1 | X41: 1 | Y41: 1 | Z41: 1 | AA41: 1 | AB41: 1 | AC41: 1 | AD41: 1 | AE41: 1 | AF41: 1 | AG41: 1 | AH41: 1 | AI41: 1 | AJ41: 1 | AK41: 1 | AL41: 1 | AM41: 1 | AN41: 1 | AO41: 1 | AP41: 1
B42: 2.3.1.6 | C42: Багц-6.6 | D42: "Сэлбэ дэд төв"-ийн барилгажилтын төслийн ХТП, РП-ний тоноглол, барилга угсралтын ажил (B хэсэг) | F42: 0.10096602 | G42: =+F42*G36 -> 0.0010326975 | N42: 1 | O42: 1 | P42: 1 | Q42: 1 | R42: 1 | S42: 1 | T42: 1 | U42: 1 | V42: 1 | W42: 1 | X42: 1 | Y42: 1 | Z42: 1 | AA42: 1 | AB42: 1 | AC42: 1 | AD42: 1 | AE42: 1 | AF42: 1 | AG42: 1 | AH42: 1 | AI42: 1 | AJ42: 1 | AK42: 1 | AL42: 1 | AM42: 1 | AN42: 1 | AO42: 1 | AP42: 1
...

Sheet Төсөл төлөвлөгөө биелэлт
X1: ТЭЗҮ Зураг төсл | Y1: =+(G7*S7+G9*S9)/15% -> 0.94682301
B2: ТӨСЛИЙН ГҮЙЦЭТГЭЛ | X2: Барилга угсралт | Y2: =+S528 -> 0.26090144
B4: Д/Д | C4: Багцын дугаар | D4: Ажлын нэр | E4: Урьдчилсан төсөвт өртөг | F4: Хэсэгт эзлэх | G4: Төсөлд эзлэх хувь | H4: Гэрээ/Хавсралт 5 | J4: Гүйцэтгэгч | L4: ОСНАУГ/Газар чөлөөлөлт/ хуулийн маргаан/Өндөржилт нөлөөлөл | N4: Төлөвлөгөөт хувь Гэрээ Хавсралт 5 | O4: Төлөвлөгөөт хувь Гэрээ-Газар чөлөөлөлт хуулийн маргаан хассан Хавсралт 5 | P4: Төлөвлөгөөт хувь Гүйцэтгэгч | Q4: Төлөвлөгөөт хувь Next week | R4: Төлөвлөгөөт хувь Өмнө долоо хоног | S4: Гүйцэтгэлийн хувь | T4: Төлөвлөгөө биелэлт Гэрээ | U4: Төлөвлөгөө биелэлт Гэрээ-Газар чөлөөлөлт хуулийн маргаан хассан | V4: Төлөвлөгөө биелэлт- Гүйцэтгэгч | W4: Төлөвлөгөө биелэлт Weekly
H5: Төлөвлөгөөт эхлэх | I5: Төлөвлөгөөт дуусах | J5: Төлөвлөгөөт эхлэх | K5: Төлөвлөгөөт дуусах | L5: Бодит Эхлэх | M5: Бодит дуусах
B6: ТӨСЛИЙН НИЙТ ГҮЙЦЭТГЭЛ | E6: =E7+E9+E528 -> 2.4958419e+12 | G6: =+G7+G9+G83+G268+G342+G528+G904+G909 -> 1 | N6: =+$G7*N7+$G9*N9+$G83*N83+$G268*N268+$G342*N342+$G528*N528+$G904*N904+$G909*N909 -> 0.71852661 | O6: =+$G7*O7+$G9*O9+$G83*O83+$G268*O268+$G342*O342+$G528*O528+$G904*O904+$G909*O909 -> 0.63730515 | P6: =+$G7*P7+$G9*P9+$G83*P83+$G268*P268+$G342*P342+$G528*P528+$G904*P904+$G909*P909 -> 0.59395469 | Q6: =+$G7*Q7+$G9*Q9+$G83*Q83+$G268*Q268+$G342*Q342+$G528*Q528+$G904*Q904+$G909*Q909 -> 0.39658204 | R6: =+$G7*R7+$G9*R9+$G83*R83+$G268*R268+$G342*R342+$G528*R528+$G904*R904+$G909*R909 -> 0.39221357 | S6: =+$G7*S7+$G9*S9+$G83*S83+$G268*S268+$G342*S342+$G528*S528+$G904*S904+$G909*S909 -> 0.39340923 | T6: =+IF(N6=0,0,$S6/N6) -> 0.54752215 | U6: =+IF(O6=0,0,$S6/O6) -> 0.6173012 | V6: =+IF(P6=0,0,$S6/P6) -> 0.66235563 | W6: =+IF(R6=0,0,$S6/R6) -> 1.0030485
B7: 1 | D7: ТЭЗҮ | E7: =E8 -> 3553800000 | G7: 0.05 | H7: 45390 | I7: 45555 | N7: =+($F8*N8) -> 1 | O7: =+($F8*O8) -> 1 | P7: =+($F8*P8) -> 1 | Q7: =+($F8*Q8) -> 1 | R7: =+($F8*R8) -> 1 | S7: =+($F8*S8) -> 1 | T7: =+IF(N7=0,0,$S7/N7) -> 1 | U7: =+IF(O7=0,0,$S7/O7) -> 1 | V7: =+IF(P7=0,0,$S7/P7) -> 1 | W7: =+IF(R7=0,0,$S7/R7) -> 1
B8: 1.1 | C8: БАГЦ 1-6 БАГЦ 8-17 | D8: "Сэлбэ дэд төв" орчмын гэр хорооллыг дахин төлөвлөн орон сууцжуулах төслийн ТЭЗҮ, барилгажилтын төсөл, олон улсын зөвлөх үйлчилгээ, зураг төслийг боловсруулах ажил | E8: 3553800000 | F8: 1 | G8: =+F8*G7 -> 0.05 | N8: 1 | O8: 1 | P8: 1 | Q8: 1 | R8: 1 | S8: 1 | T8: =+IF(N8=0,0,$S8/N8) -> 1 | U8: =+IF(O8=0,0,$S8/O8) -> 1 | V8: =+IF(P8=0,0,$S8/P8) -> 1 | W8: =+IF(R8=0,0,$S8/R8) -> 1
B9: 2 | D9: Ажлын зураг төсөл | E9: =E10+E61+E62 -> 8220164289 | G9: 0.1 | H9: 45390 | I9: 45884 | N9: =+($F10*N10+$F61*N61+$F62*N62) -> 0.98781562 | O9: =+($F10*O10+$F61*O61+$F62*O62) -> 0.98781562 | P9: =+($F10*P10+$F61*P61+$F62*P62) -> 0.98781562 | Q9: =(F10*Q10+F61*Q61+F62*Q62+F70*Q70) -> 0.92023451 | R9: =($F10*R10+$F61*R61+$F62*R62+$F70*R70) -> 0.92023451 | S9: =($F10*S10+$F61*S61+$F62*S62+$F70*S70) -> 0.92023451 | T9: =+IF(N9=0,0,$S9/N9) -> 0.9315853 | U9: =+IF(O9=0,0,$S9/O9) -> 0.9315853 | V9: =+IF(P9=0,0,$S9/P9) -> 0.9315853 | W9: =+IF(R9=0,0,$S9/R9) -> 1
B10: 2.1 | C10: БАГЦ 1-6 БАГЦ 10-17 | D10: "Сэлбэ дэд төв" орчмын гэр хорооллыг дахин төлөвлөн орон сууцжуулах төслийн ТЭЗҮ, барилгажилтын төсөл, олон улсын зөвлөх үйлчилгээ, зураг төслийг боловсруулах ажил (Барилгажилты төсөл Хувилбар 2) нэмэлт ажил | E10: 533070000 | F10: 0.666 | G10: =+F10*G9 -> 0.0666 | N10: =$F11*N11+$F19*N19+$F35*N35 -> 0.98170514 | O10: =$F11*O11+$F19*O19+$F35*O35 -> 0.98170514 | P10: =$F11*P11+$F19*P19+$F35*P35 -> 0.98170514 | Q10: =$F11*Q11+$F19*Q19+$F35*Q35 -> 0.97452448 | R10: =$F11*R11+$F19*R19+$F35*R35 -> 0.97452448 | S10: =$F11*S11+$F19*S19+$F35*S35 -> 0.97452448 | T10: =+IF(N10=0,0,$S10/N10) -> 0.99268552 | U10: =+IF(O10=0,0,$S10/O10) -> 0.99268552 | V10: =+IF(P10=0,0,$S10/P10) -> 0.99268552 | W10: =+IF(R10=0,0,$S10/R10) -> 1
B11: 2.1.1 | C11: Багц- 1-4 | D11: Орон сууцны хороолол барилга угсралт | F11: =F719 -> 0.78107172 | G11: =+F11*G9 -> 0.078107172 | N11: =+$F12*N12+$F13*N13+$F14*N14+$F15*N15+$F16*N16+$F17*N17+$F18*N18 -> 1 | O11: =+$F12*O12+$F13*O13+$F14*O14+$F15*O15+$F16*O16+$F17*O17+$F18*O18 -> 1 | P11: =+$F12*P12+$F13*P13+$F14*P14+$F15*P15+$F16*P16+$F17*P17+$F18*P18 -> 1 | Q11: =+$F12*Q12+$F13*Q13+$F14*Q14+$F15*Q15+$F16*Q16+$F17*Q17+$F18*Q18 -> 1 | R11: =+$F12*R12+$F13*R13+$F14*R14+$F15*R15+$F16*R16+$F17*R17+$F18*R18 -> 1 | S11: =+$F12*S12+$F13*S13+$F14*S14+$F15*S15+$F16*S16+$F17*S17+$F18*S18 -> 1 | T11: =+IF(N11=0,0,$S11/N11) -> 1 | U11: =+IF(O11=0,0,$S11/O11) -> 1 | V11: =+IF(P11=0,0,$S11/P11) -> 1 | W11: =+IF(R11=0,0,$S11/R11) -> 1
B12: 2.1.1 | C12: Багц-1 | D12: Орон сууцны хороолол барилга угсралт | F12: 0.20095297 | G12: =+F12*G11 -> 0.015695868 | N12: 1 | O12: 1 | P12: 1 | Q12: 1 | R12: 1 | S12: 1 | T12: =+IF(N12=0,0,$S12/N12) -> 1 | U12: =+IF(O12=0,0,$S12/O12) -> 1 | V12: =+IF(P12=0,0,$S12/P12) -> 1 | W12: =+IF(R12=0,0,$S12/R12) -> 1
B13: 2.1.2 | C13: Багц-2 | D13: Орон сууцны хороолол барилга угсралт | F13: 0.24153553 | G13: =+F13*G11 -> 0.018865657 | N13: 1 | O13: 1 | P13: 1 | Q13: 1 | R13: 1 | S13: 1 | T13: =+IF(N13=0,0,$S13/N13) -> 1 | U13: =+IF(O13=0,0,$S13/O13) -> 1 | V13: =+IF(P13=0,0,$S13/P13) -> 1 | W13: =+IF(R13=0,0,$S13/R13) -> 1
B14: 2.1.3 | C14: Багц-3.1 | D14: Орон сууцны хороолол барилга угсралт | F14: 0.094678015 | G14: =+F14*G11 -> 0.007395032 | N14: 1 | O14: 1 | P14: 1 | Q14: 1 | R14: 1 | S14: 1 | T14: =+IF(N14=0,0,$S14/N14) -> 1 | U14: =+IF(O14=0,0,$S14/O14) -> 1 | V14: =+IF(P14=0,0,$S14/P14) -> 1 | W14: =+IF(R14=0,0,$S14/R14) -> 1
B15: 2.1.4 | C15: Багц-3.2 | D15: Орон сууцны хороолол барилга угсралт | F15: 0.10115553 | G15: =+F15*G11 -> 0.0079009722 | N15: 1 | O15: 1 | P15: 1 | Q15: 1 | R15: 1 | S15: 1 | T15: =+IF(N15=0,0,$S15/N15) -> 1 | U15: =+IF(O15=0,0,$S15/O15) -> 1 | V15: =+IF(P15=0,0,$S15/P15) -> 1 | W15: =+IF(R15=0,0,$S15/R15) -> 1
B16: 2.1.5 | C16: Багц-3.3 | D16: Орон сууцны хороолол барилга угсралт | F16: 0.11541079 | G16: =+F16*G11 -> 0.0090144107 | N16: 1 | O16: 1 | P16: 1 | Q16: 1 | R16: 1 | S16: 1 | T16: =+IF(N16=0,0,$S16/N16) -> 1 | U16: =+IF(O16=0,0,$S16/O16) -> 1 | V16: =+IF(P16=0,0,$S16/P16) -> 1 | W16: =+IF(R16=0,0,$S16/R16) -> 1
B17: 2.1.6 | C17: Багц-4.1 | D17: Орон сууцны хороолол барилга угсралт | F17: 0.13984312 | G17: =+F17*G11 -> 0.010922751 | N17: 1 | O17: 1 | P17: 1 | Q17: 1 | R17: 1 | S17: 1 | T17: =+IF(N17=0,0,$S17/N17) -> 1 | U17: =+IF(O17=0,0,$S17/O17) -> 1 | V17: =+IF(P17=0,0,$S17/P17) -> 1 | W17: =+IF(R17=0,0,$S17/R17) -> 1
B18: 2.1.7 | C18: Багц-4.2 | D18: Орон сууцны хороолол барилга угсралт | F18: 0.10642405 | G18: =+F18*G11 -> 0.0083124812 | N18: 1 | O18: 1 | P18: 1 | Q18: 1 | R18: 1 | S18: 1 | T18: =+IF(N18=0,0,$S18/N18) -> 1 | U18: =+IF(O18=0,0,$S18/O18) -> 1 | V18: =+IF(P18=0,0,$S18/P18) -> 1 | W18: =+IF(R18=0,0,$S18/R18) -> 1
B19: 2.1.2 | C19: Багц-16, 17 | D19: ГАДНА ТОХИЖИЛТ, ӨНДӨРЖИЛТ | F19: =F842 -> 0.039032542 | G19: =+F19*G9 -> 0.0039032542 | N19: =+SUMPRODUCT($F20:$F34,N20:N34) -> 0.53129205 | O19: =+SUMPRODUCT($F20:$F34,O20:O34) -> 0.53129205 | P19: =+SUMPRODUCT($F20:$F34,P20:P34) -> 0.53129205 | Q19: =+SUMPRODUCT($F20:$F34,Q20:Q34) -> 0.90709062 | R19: =+SUMPRODUCT($F20:$F34,R20:R34) -> 0.90709062 | S19: =+SUMPRODUCT($F20:$F34,S20:S34) -> 0.90709062 | T19: =+IF(N19=0,0,$S19/N19) -> 1.7073296 | U19: =+IF(O19=0,0,$S19/O19) -> 1.7073296 | V19: =+IF(P19=0,0,$S19/P19) -> 1.7073296 | W19: =+IF(R19=0,0,$S19/R19) -> 1
B20: 2.2.1 | C20: БАГЦ-16.1 | D20: Өндөржилтийн ажил БАГЦ 1 | F20: =F843 -> 0.092877611 | G20: =+F20*G19 -> 0.00036252493 | N20: 1 | O20: 1 | P20: 1 | Q20: 1 | R20: 1 | S20: 1 | T20: =+IF(N20=0,0,$S20/N20) -> 1 | U20: =+IF(O20=0,0,$S20/O20) -> 1 | V20: =+IF(P20=0,0,$S20/P20) -> 1 | W20: =+IF(R20=0,0,$S20/R20) -> 1
B21: 2.2.2 | C21: БАГЦ-16.2 | D21: Өндөржилтийн ажил БАГЦ 2 | F21: =F844 -> 0.058105219 | G21: =+F21*G19 -> 0.00022679944 | N21: 1 | O21: 1 | P21: 1 | Q21: 1 | R21: 1 | S21: 1 | T21: =+IF(N21=0,0,$S21/N21) -> 1 | U21: =+IF(O21=0,0,$S21/O21) -> 1 | V21: =+IF(P21=0,0,$S21/P21) -> 1 | W21: =+IF(R21=0,0,$S21/R21) -> 1
B22: 2.2.3 | C22: БАГЦ-16.3 | D22: Өндөржилтийн ажил БАГЦ 3.1 | F22: =F845 -> 0.027796911 | G22: =+F22*G19 -> 0.00010849841 | N22: 1 | O22: 1 | P22: 1 | Q22: 1 | R22: 1 | S22: 1 | T22: =+IF(N22=0,0,$S22/N22) -> 1 | U22: =+IF(O22=0,0,$S22/O22) -> 1 | V22: =+IF(P22=0,0,$S22/P22) -> 1 | W22: =+IF(R22=0,0,$S22/R22) -> 1
B23: 2.2.4 | C23: БАГЦ-16.4 | D23: Өндөржилтийн ажил БАГЦ 3.2 | F23: =F846 -> 0.0291553 | G23: =+F23*G19 -> 0.00011380055 | N23: 1 | O23: 1 | P23: 1 | Q23: 1 | R23: 1 | S23: 1 | T23: =+IF(N23=0,0,$S23/N23) -> 1 | U23: =+IF(O23=0,0,$S23/O23) -> 1 | V23: =+IF(P23=0,0,$S23/P23) -> 1 | W23: =+IF(R23=0,0,$S23/R23) -> 1
B24: 2.2.5 | C24: БАГЦ-16.5 | D24: Өндөржилтийн ажил БАГЦ 3.3 | F24: =F847 -> 0.040182802 | G24: =+F24*G19 -> 0.00015684369 | N24: 1 | O24: 1 | P24: 1 | Q24: 1 | R24: 1 | S24: 1 | T24: =+IF(N24=0,0,$S24/N24) -> 1 | U24: =+IF(O24=0,0,$S24/O24) -> 1 | V24: =+IF(P24=0,0,$S24/P24) -> 1 | W24: =+IF(R24=0,0,$S24/R24) -> 1
B25: 2.2.6 | C25: БАГЦ-16.6 | D25: Өндөржилтийн ажил БАГЦ 4.1 | F25: =F848 -> 0.098615014 | G25: =+F25*G19 -> 0.00038491947 | N25: 1 | O25: 1 | P25: 1 | Q25: 1 | R25: 1 | S25: 1 | T25: =+IF(N25=0,0,$S25/N25) -> 1 | U25: =+IF(O25=0,0,$S25/O25) -> 1 | V25: =+IF(P25=0,0,$S25/P25) -> 1 | W25: =+IF(R25=0,0,$S25/R25) -> 1
B26: 2.2.7 | C26: БАГЦ-16.7 | D26: Өндөржилтийн ажил БАГЦ 4.2 | F26: =F849 -> 0.091649809 | G26: =+F26*G19 -> 0.00035773251 | N26: 1 | O26: 1 | P26: 1 | Q26: 1 | R26: 1 | S26: 1 | T26: =+IF(N26=0,0,$S26/N26) -> 1 | U26: =+IF(O26=0,0,$S26/O26) -> 1 | V26: =+IF(P26=0,0,$S26/P26) -> 1 | W26: =+IF(R26=0,0,$S26/R26) -> 1
B27: 2.2.8 | C27: БАГЦ-16.8 | D27: Өндөржилтийн ажил Олон нийтийн бүсийн ГИШС | F27: =F850 -> 0.092909381 | G27: =+F27*G19 -> 0.00036264893 | N27: 1 | O27: 1 | P27: 1 | Q27: 0 | R27: 0 | S27: 0 | T27: =+IF(N27=0,0,$S27/N27) -> 0 | U27: =+IF(O27=0,0,$S27/O27) -> 0 | V27: =+IF(P27=0,0,$S27/P27) -> 0 | W27: =+IF(R27=0,0,$S27/R27) -> 0
B28: 2.2.9 | C28: БАГЦ-17.1 | D28: Гадна тохижилтийн ажил БАГЦ 1 | F28: =F851 -> 0.080887029 | G28: =+F28*G19 -> 0.00031572264 | Q28: 1 | R28: 1 | S28: 1 | T28: =+IF(N28=0,0,$S28/N28) -> 0 | U28: =+IF(O28=0,0,$S28/O28) -> 0 | V28: =+IF(P28=0,0,$S28/P28) -> 0 | W28: =+IF(R28=0,0,$S28/R28) -> 1
B29: 2.2.10 | C29: БАГЦ-17.2 | D29: Гадна тохижилтийн ажил БАГЦ 2 | F29: =F852 -> 0.11788368 | G29: =+F29*G19 -> 0.00046012997 | Q29: 1 | R29: 1 | S29: 1 | T29: =+IF(N29=0,0,$S29/N29) -> 0 | U29: =+IF(O29=0,0,$S29/O29) -> 0 | V29: =+IF(P29=0,0,$S29/P29) -> 0 | W29: =+IF(R29=0,0,$S29/R29) -> 1
B30: 2.2.11 | C30: БАГЦ-17.3 | D30: Гадна тохижилтийн ажил БАГЦ 3.1 | F30: =F853 -> 0.041046639 | G30: =+F30*G19 -> 0.00016021547 | Q30: 1 | R30: 1 | S30: 1 | T30: =+IF(N30=0,0,$S30/N30) -> 0 | U30: =+IF(O30=0,0,$S30/O30) -> 0 | V30: =+IF(P30=0,0,$S30/P30) -> 0 | W30: =+IF(R30=0,0,$S30/R30) -> 1
B31: 2.2.12 | C31: БАГЦ-17.4 | D31: Гадна тохижилтийн ажил БАГЦ 3.2 | F31: =F854 -> 0.053741978 | G31: =+F31*G19 -> 0.0002097686 | Q31: 1 | R31: 1 | S31: 1 | T31: =+IF(N31=0,0,$S31/N31) -> 0 | U31: =+IF(O31=0,0,$S31/O31) -> 0 | V31: =+IF(P31=0,0,$S31/P31) -> 0 | W31: =+IF(R31=0,0,$S31/R31) -> 1
B32: 2.2.13 | C32: БАГЦ-17.5 | D32: Гадна тохижилтийн ажил БАГЦ 3.3 | F32: =F855 -> 0.058057395 | G32: =+F32*G19 -> 0.00022661277 | Q32: 1 | R32: 1 | S32: 1 | T32: =+IF(N32=0,0,$S32/N32) -> 0 | U32: =+IF(O32=0,0,$S32/O32) -> 0 | V32: =+IF(P32=0,0,$S32/P32) -> 0 | W32: =+IF(R32=0,0,$S32/R32) -> 1
B33: 2.2.14 | C33: БАГЦ-17.6 | D33: Гадна тохижилтийн ажил БАГЦ 4.1 | F33: =F856 -> 0.061612727 | G33: =+F33*G19 -> 0.00024049014 | Q33: 1 | R33: 1 | S33: 1 | T33: =+IF(N33=0,0,$S33/N33) -> 0 | U33: =+IF(O33=0,0,$S33/O33) -> 0 | V33: =+IF(P33=0,0,$S33/P33) -> 0 | W33: =+IF(R33=0,0,$S33/R33) -> 1
B34: 2.2.15 | C34: БАГЦ-17.7 | D34: Гадна тохижилтийн ажил БАГЦ 4.2 | F34: =F857 -> 0.055478507 | G34: =+F34*G19 -> 0.00021654672 | Q34: 1 | R34: 1 | S34: 1 | T34: =+IF(N34=0,0,$S34/N34) -> 0 | U34: =+IF(O34=0,0,$S34/O34) -> 0 | V34: =+IF(P34=0,0,$S34/P34) -> 0 | W34: =+IF(R34=0,0,$S34/R34) -> 1
B35: 2.1.3 | C35: Багц- 5,6 9-15 | D35: ИНЖЕНЕРИЙН ДЭД БҮТЭЦ | F35: =F858 -> 0.17989574 | G35: =+F35*G9 -> 0.017989574 | N35: =+$F36*N36+$F48*N48+$F56*N56 -> 1 | O35: =+$F36*O36+$F48*O48+$F56*O56 -> 1 | P35: =+$F36*P36+$F48*P48+$F56*P56 -> 1 | Q35: =+$F36*Q36+$F48*Q48+$F56*Q56 -> 0.87854613 | R35: =+$F36*R36+$F48*R48+$F56*R56 -> 0.87854613 | S35: =+$F36*S36+$F48*S48+$F56*S56 -> 0.87854613 | T35: =+IF(N35=0,0,$S35/N35) -> 0.87854613 | U35: =+IF(O35=0,0,$S35/O35) -> 0.87854613 | V35: =+IF(P35=0,0,$S35/P35) -> 0.87854613 | W35: =+IF(R35=0,0,$S35/R35) -> 1
B36: 2.3.1 | C36: Багц 6 | D36: Гадна цахилгаан, холбоо дохиолол | F36: 0.5685609 | G36: =+F36*G35 -> 0.010228168 | N36: =+SUMPRODUCT($F37:$F47,N37:N47) -> 1 | O36: =+SUMPRODUCT($F37:$F47,O37:O47) -> 1 | P36: =+SUMPRODUCT($F37:$F47,P37:P47) -> 1 | Q36: =+SUMPRODUCT($F37:$F47,Q37:Q47) -> 0.86016081 | R36: =+SUMPRODUCT($F37:$F47,R37:R47) -> 0.86016081 | S36: =+SUMPRODUCT($F37:$F47,S37:S47) -> 0.86016081 | T36: =+IF(N36=0,0,$S36/N36) -> 0.86016081 | U36: =+IF(O36=0,0,$S36/O36) -> 0.86016081 | V36: =+IF(P36=0,0,$S36/P36) -> 0.86016081 | W36: =+IF(R36=0,0,$S36/R36) -> 1
B37: 2.3.1.1 | C37: Багц-6.1 | D37: Багц 1 Гадна цахилгаан, холбоо дохиолол | F37: 0.050651268 | G37: =+F37*G36 -> 0.0005180697 | N37: 1 | O37: 1 | P37: 1 | Q37: 1 | R37: 1 | S37: 1 | T37: =+IF(N37=0,0,$S37/N37) -> 1 | U37: =+IF(O37=0,0,$S37/O37) -> 1 | V37: =+IF(P37=0,0,$S37/P37) -> 1 | W37: =+IF(R37=0,0,$S37/R37) -> 1
B38: 2.3.1.2 | C38: Багц-6.2 | D38: Багц 2 Гадна цахилгаан, холбоо дохиолол | F38: 0.082125454 | G38: =+F38*G36 -> 0.00083999298 | N38: 1 | O38: 1 | P38: 1 | Q38: 1 | R38: 1 | S38: 1 | T38: =+IF(N38=0,0,$S38/N38) -> 1 | U38: =+IF(O38=0,0,$S38/O38) -> 1 | V38: =+IF(P38=0,0,$S38/P38) -> 1 | W38: =+IF(R38=0,0,$S38/R38) -> 1
B39: 2.3.1.3 | C39: Багц-6.3 | D39: Багц 3 Гадна цахилгаан, холбоо дохиолол | F39: 0.066964931 | G39: =+F39*G36 -> 0.0006849286 | N39: 1 | O39: 1 | P39: 1 | Q39: 1 | R39: 1 | S39: 1 | T39: =+IF(N39=0,0,$S39/N39) -> 1 | U39: =+IF(O39=0,0,$S39/O39) -> 1 | V39: =+IF(P39=0,0,$S39/P39) -> 1 | W39: =+IF(R39=0,0,$S39/R39) -> 1
B40: 2.3.1.4 | C40: Багц-6.4 | D40: Багц 4 Гадна цахилгаан, холбоо дохиолол | F40: 0.082833365 | G40: =+F40*G36 -> 0.00084723361 | N40: 1 | O40: 1 | P40: 1 | Q40: 1 | R40: 1 | S40: 1 | T40: =+IF(N40=0,0,$S40/N40) -> 1 | U40: =+IF(O40=0,0,$S40/O40) -> 1 | V40: =+IF(P40=0,0,$S40/P40) -> 1 | W40: =+IF(R40=0,0,$S40/R40) -> 1
B41: 2.3.1.5 | C41: Багц-6.5 | D41: "Сэлбэ дэд төв"-ийн барилгажилтын төслийн ХТП, РП-ний тоноглол, барилга угсралтын ажил (A хэсэг) | F41: 0.18485404 | G41: =+F41*G36 -> 0.0018907182 | N41: 1 | O41: 1 | P41: 1 | Q41: 1 | R41: 1 | S41: 1 | T41: =+IF(N41=0,0,$S41/N41) -> 1 | U41: =+IF(O41=0,0,$S41/O41) -> 1 | V41: =+IF(P41=0,0,$S41/P41) -> 1 | W41: =+IF(R41=0,0,$S41/R41) -> 1
...

Sheet Барилга угсралт дүгнэлт
A1: БАРИЛГА УГСРАЛТ - ОРОН СУУЦНЫ БАГЦУУДЫН ДҮГНЭЛТ
A2: Эх сурвалж: Level 4 (Төмөр бетон рамын ажил - давхар бүрийн цутгалтын бодит гүйцэтгэл; Багц-3.2 нь Талбайн мэдээллийн самбараар шинэчлэгдсэн). Давхрын гүйцэтгэл 0%-аас их бол тухайн давхрын цутгалтыг 'эхэлсэн' гэж, 100% бол 'цутгасан' гэж тооцсон. Бүх давхарт ижил хувь орсон блокийг давхрын задаргаагүй гэж тусад нь ангилав. Огноо: 2026-10-05
A4: 1. БҮХ БАГЦУУДЫН ЕРӨНХИЙ ГҮЙЦЭТГЭЛ
A5: Багц | B5: Нийт блок | C5: Техник давхар дууссан блок | D5: Угсралт эхэлсэн блок (давхраар болон блокийн хувиар) | E5: Угсралт эхлээгүй блок | F5: Эхлээгүй блокууд (дугаар) | G5: Төлөвлөгөөний биелэлт (Next week) | H5: Гүйцэтгэлийн хувь | I5: Дэлгэрэнгүй
A6: Багц-1 | B6: =COUNTA(A69:A88) -> 20 | C6: =COUNTIFS(F69:F88,"Дууссан") -> 14 | D6: =COUNTIFS(D69:D88,">0")+COUNTIFS(G69:G88,"Блокийн*") -> 19 | E6: =COUNTIFS(G69:G88,"Эхлээгүй") -> 1 | F6: {=IF(E6=0,"-",_xlfn.TEXTJOIN(", ",TRUE,IF(G69:G88="Эхлээгүй",A69:A88,"")))} -> 5/8 | G6: ='Төсөл төлөвлөгөө биелэлт'!Q720 -> 0.2868 | H6: ='Төсөл төлөвлөгөө биелэлт'!S720 -> 0.2823 | I6: 17-р мөрөөс
A7: Багц-2 | B7: =COUNTA(A101:A126) -> 26 | C7: =COUNTIFS(F101:F126,"Дууссан") -> 25 | D7: =COUNTIFS(D101:D126,">0")+COUNTIFS(G101:G126,"Блокийн*") -> 26 | E7: =COUNTIFS(G101:G126,"Эхлээгүй") -> 0 | F7: {=IF(E7=0,"-",_xlfn.TEXTJOIN(", ",TRUE,IF(G101:G126="Эхлээгүй",A101:A126,"")))} -> - | G7: ='Төсөл төлөвлөгөө биелэлт'!Q741 -> 0.317 | H7: ='Төсөл төлөвлөгөө биелэлт'!S741 -> 0.3153 | I7: 54-р мөрөөс
A8: Багц-3.1 | B8: =COUNTA(A138:A148) -> 11 | C8: =COUNTIFS(F138:F148,"Дууссан") -> 0 | D8: =COUNTIFS(D138:D148,">0")+COUNTIFS(G138:G148,"Блокийн*") -> 0 | E8: =COUNTIFS(G138:G148,"Эхлээгүй") -> 11 | F8: {=IF(E8=0,"-",_xlfn.TEXTJOIN(", ",TRUE,IF(G138:G148="Эхлээгүй",A138:A148,"")))} -> 5/1, 5/2, 5/3, 5/4, 5/5, 5/6, 5/7, 5/8, 5/9, 5/10, 5/11 | G8: ='Төсөл төлөвлөгөө биелэлт'!Q768 -> 0.007 | H8: ='Төсөл төлөвлөгөө биелэлт'!S768 -> 0.007 | I8: 92-р мөрөөс
A9: Багц-3.2 | B9: =COUNTA(A163:A174) -> 12 | C9: =COUNTIFS(F163:F174,"Дууссан") -> 9 | D9: =COUNTIFS(D163:D174,">0")+COUNTIFS(G163:G174,"Блокийн*") -> 11 | E9: =COUNTIFS(G163:G174,"Эхлээгүй") -> 1 | F9: {=IF(E9=0,"-",_xlfn.TEXTJOIN(", ",TRUE,IF(G163:G174="Эхлээгүй",A163:A174,"")))} -> 5/1 | G9: ='Төсөл төлөвлөгөө биелэлт'!Q780 -> 0.3096 | H9: ='Төсөл төлөвлөгөө биелэлт'!S780 -> 0.3032 | I9: 114-р мөрөөс
A10: Багц-3.3 | B10: =COUNTA(A188:A201) -> 14 | C10: =COUNTIFS(F188:F201,"Дууссан") -> 9 | D10: =COUNTIFS(D188:D201,">0")+COUNTIFS(G188:G201,"Блокийн*") -> 12 | E10: =COUNTIFS(G188:G201,"Эхлээгүй") -> 2 | F10: {=IF(E10=0,"-",_xlfn.TEXTJOIN(", ",TRUE,IF(G188:G201="Эхлээгүй",A188:A201,"")))} -> 5/9, 5/10 | G10: ='Төсөл төлөвлөгөө биелэлт'!Q793 -> 0.3124 | H10: ='Төсөл төлөвлөгөө биелэлт'!S793 -> 0.3015 | I10: 140-р мөрөөс
A11: Багц-4.1 | B11: =COUNTA(A213:A228) -> 16 | C11: =COUNTIFS(F213:F228,"Дууссан") -> 0 | D11: =COUNTIFS(D213:D228,">0")+COUNTIFS(G213:G228,"Блокийн*") -> 16 | E11: =COUNTIFS(G213:G228,"Эхлээгүй") -> 0 | F11: {=IF(E11=0,"-",_xlfn.TEXTJOIN(", ",TRUE,IF(G213:G228="Эхлээгүй",A213:A228,"")))} -> - | G11: ='Төсөл төлөвлөгөө биелэлт'!Q808 -> 0.3262 | H11: ='Төсөл төлөвлөгөө биелэлт'!S808 -> 0.3204 | I11: 167-р мөрөөс
A12: Багц-4.2 | B12: =COUNTA(A241:A254) -> 14 | C12: =COUNTIFS(F241:F254,"Дууссан") -> 0 | D12: =COUNTIFS(D241:D254,">0")+COUNTIFS(G241:G254,"Блокийн*") -> 9 | E12: =COUNTIFS(G241:G254,"Эхлээгүй") -> 5 | F12: {=IF(E12=0,"-",_xlfn.TEXTJOIN(", ",TRUE,IF(G241:G254="Эхлээгүй",A241:A254,"")))} -> 5/2, 6/5, 6/6, 6/7, 6/8 | G12: ='Төсөл төлөвлөгөө биелэлт'!Q826 -> 0.0906 | H12: ='Төсөл төлөвлөгөө биелэлт'!S826 -> 0.072 | I12: 194-р мөрөөс
A13: Барилга угсралт (нийт) | B13: =SUM(B6:B12) -> 113 | C13: =SUM(C6:C12) -> 57 | D13: =SUM(D6:D12) -> 93 | E13: =SUM(E6:E12) -> 20 | F13: - | G13: ='Төсөл төлөвлөгөө биелэлт'!Q528 -> 0.26491764 | H13: 0.27844947
A15: ДАВХРУУДЫН НЭГТГЭЛ: Төслийн блокууд хэдэн давхарт явж байгаа (блокийн тоогоор)
A16: Блок бүрийн давхар = цутгалт эхэлсэн хамгийн дээд давхар. 'Техник давхар дууссан' гэдэгт каркас бүрэн дууссан блок орно.
A17: 1) 12 давхар барилга (1-12F)
A18: Давхар (блок хүрсэн шат) | B18: Багц-1 | C18: Багц-2 | D18: Багц-4.2 | E18: Нийт блок
A19: Угсралт эхлээгүй | B19: =COUNTIFS($G$69:$G$88,"Эхлээгүй",$C$69:$C$88,12) -> 0 | C19: =COUNTIFS($G$101:$G$126,"Эхлээгүй",$C$101:$C$126,12) -> 0 | D19: =COUNTIFS($G$241:$G$254,"Эхлээгүй",$C$241:$C$254,12) -> 4 | E19: =SUM(B19:D19) -> 4
A20: Зөвхөн зоорь/суурь (давхар цутгалт эхлээгүй) | B20: =COUNTIFS($G$69:$G$88,"Зоорь*",$C$69:$C$88,12)+COUNTIFS($G$69:$G$88,"Зөвхөн*",$C$69:$C$88,12) -> 0 | C20: =COUNTIFS($G$101:$G$126,"Зоорь*",$C$101:$C$126,12)+COUNTIFS($G$101:$G$126,"Зөвхөн*",$C$101:$C$126,12) -> 0 | D20: =COUNTIFS($G$241:$G$254,"Зоорь*",$C$241:$C$254,12)+COUNTIFS($G$241:$G$254,"Зөвхөн*",$C$241:$C$254,12) -> 0 | E20: =SUM(B20:D20) -> 0
A21: 1F-д явж байгаа | B21: =COUNTIFS($D$69:$D$88,1,$F$69:$F$88,"Хийгдээгүй",$C$69:$C$88,12) -> 0 | C21: =COUNTIFS($D$101:$D$126,1,$F$101:$F$126,"Хийгдээгүй",$C$101:$C$126,12) -> 0 | D21: =COUNTIFS($D$241:$D$254,1,$F$241:$F$254,"Хийгдээгүй",$C$241:$C$254,12) -> 0 | E21: =SUM(B21:D21) -> 0
A22: 2F-д явж байгаа | B22: =COUNTIFS($D$69:$D$88,2,$F$69:$F$88,"Хийгдээгүй",$C$69:$C$88,12) -> 0 | C22: =COUNTIFS($D$101:$D$126,2,$F$101:$F$126,"Хийгдээгүй",$C$101:$C$126,12) -> 0 | D22: =COUNTIFS($D$241:$D$254,2,$F$241:$F$254,"Хийгдээгүй",$C$241:$C$254,12) -> 0 | E22: =SUM(B22:D22) -> 0
A23: 3F-д явж байгаа | B23: =COUNTIFS($D$69:$D$88,3,$F$69:$F$88,"Хийгдээгүй",$C$69:$C$88,12) -> 0 | C23: =COUNTIFS($D$101:$D$126,3,$F$101:$F$126,"Хийгдээгүй",$C$101:$C$126,12) -> 0 | D23: =COUNTIFS($D$241:$D$254,3,$F$241:$F$254,"Хийгдээгүй",$C$241:$C$254,12) -> 0 | E23: =SUM(B23:D23) -> 0
A24: 4F-д явж байгаа | B24: =COUNTIFS($D$69:$D$88,4,$F$69:$F$88,"Хийгдээгүй",$C$69:$C$88,12) -> 0 | C24: =COUNTIFS($D$101:$D$126,4,$F$101:$F$126,"Хийгдээгүй",$C$101:$C$126,12) -> 0 | D24: =COUNTIFS($D$241:$D$254,4,$F$241:$F$254,"Хийгдээгүй",$C$241:$C$254,12) -> 0 | E24: =SUM(B24:D24) -> 0
A25: 5F-д явж байгаа | B25: =COUNTIFS($D$69:$D$88,5,$F$69:$F$88,"Хийгдээгүй",$C$69:$C$88,12) -> 0 | C25: =COUNTIFS($D$101:$D$126,5,$F$101:$F$126,"Хийгдээгүй",$C$101:$C$126,12) -> 0 | D25: =COUNTIFS($D$241:$D$254,5,$F$241:$F$254,"Хийгдээгүй",$C$241:$C$254,12) -> 0 | E25: =SUM(B25:D25) -> 0
A26: 6F-д явж байгаа | B26: =COUNTIFS($D$69:$D$88,6,$F$69:$F$88,"Хийгдээгүй",$C$69:$C$88,12) -> 1 | C26: =COUNTIFS($D$101:$D$126,6,$F$101:$F$126,"Хийгдээгүй",$C$101:$C$126,12) -> 0 | D26: =COUNTIFS($D$241:$D$254,6,$F$241:$F$254,"Хийгдээгүй",$C$241:$C$254,12) -> 0 | E26: =SUM(B26:D26) -> 1
A27: 7F-д явж байгаа | B27: =COUNTIFS($D$69:$D$88,7,$F$69:$F$88,"Хийгдээгүй",$C$69:$C$88,12) -> 0 | C27: =COUNTIFS($D$101:$D$126,7,$F$101:$F$126,"Хийгдээгүй",$C$101:$C$126,12) -> 0 | D27: =COUNTIFS($D$241:$D$254,7,$F$241:$F$254,"Хийгдээгүй",$C$241:$C$254,12) -> 0 | E27: =SUM(B27:D27) -> 0
A28: 8F-д явж байгаа | B28: =COUNTIFS($D$69:$D$88,8,$F$69:$F$88,"Хийгдээгүй",$C$69:$C$88,12) -> 0 | C28: =COUNTIFS($D$101:$D$126,8,$F$101:$F$126,"Хийгдээгүй",$C$101:$C$126,12) -> 0 | D28: =COUNTIFS($D$241:$D$254,8,$F$241:$F$254,"Хийгдээгүй",$C$241:$C$254,12) -> 0 | E28: =SUM(B28:D28) -> 0
A29: 9F-д явж байгаа | B29: =COUNTIFS($D$69:$D$88,9,$F$69:$F$88,"Хийгдээгүй",$C$69:$C$88,12) -> 0 | C29: =COUNTIFS($D$101:$D$126,9,$F$101:$F$126,"Хийгдээгүй",$C$101:$C$126,12) -> 0 | D29: =COUNTIFS($D$241:$D$254,9,$F$241:$F$254,"Хийгдээгүй",$C$241:$C$254,12) -> 0 | E29: =SUM(B29:D29) -> 0
A30: 10F-д явж байгаа | B30: =COUNTIFS($D$69:$D$88,10,$F$69:$F$88,"Хийгдээгүй",$C$69:$C$88,12) -> 1 | C30: =COUNTIFS($D$101:$D$126,10,$F$101:$F$126,"Хийгдээгүй",$C$101:$C$126,12) -> 0 | D30: =COUNTIFS($D$241:$D$254,10,$F$241:$F$254,"Хийгдээгүй",$C$241:$C$254,12) -> 0 | E30: =SUM(B30:D30) -> 1
A31: 11F-д явж байгаа | B31: =COUNTIFS($D$69:$D$88,11,$F$69:$F$88,"Хийгдээгүй",$C$69:$C$88,12) -> 1 | C31: =COUNTIFS($D$101:$D$126,11,$F$101:$F$126,"Хийгдээгүй",$C$101:$C$126,12) -> 0 | D31: =COUNTIFS($D$241:$D$254,11,$F$241:$F$254,"Хийгдээгүй",$C$241:$C$254,12) -> 0 | E31: =SUM(B31:D31) -> 1
A32: 12F-д явж байгаа | B32: =COUNTIFS($D$69:$D$88,12,$F$69:$F$88,"Хийгдээгүй",$C$69:$C$88,12) -> 0 | C32: =COUNTIFS($D$101:$D$126,12,$F$101:$F$126,"Хийгдээгүй",$C$101:$C$126,12) -> 0 | D32: =COUNTIFS($D$241:$D$254,12,$F$241:$F$254,"Хийгдээгүй",$C$241:$C$254,12) -> 0 | E32: =SUM(B32:D32) -> 0
A33: Техник давхар хүртэл дууссан | B33: =COUNTIFS($F$69:$F$88,"Дууссан",$C$69:$C$88,12) -> 5 | C33: =COUNTIFS($F$101:$F$126,"Дууссан",$C$101:$C$126,12) -> 4 | D33: =COUNTIFS($F$241:$F$254,"Дууссан",$C$241:$C$254,12) -> 0 | E33: =SUM(B33:D33) -> 9
A34: Давхрын задаргаагүй (блокийн хувиар) | B34: =COUNTIFS($G$69:$G$88,"Блокийн*",$C$69:$C$88,12) -> 0 | C34: =COUNTIFS($G$101:$G$126,"Блокийн*",$C$101:$C$126,12) -> 0 | D34: =COUNTIFS($G$241:$G$254,"Блокийн*",$C$241:$C$254,12) -> 4 | E34: =SUM(B34:D34) -> 4
A35: Нийт блок | B35: =SUM(B19:B34) -> 8 | C35: =SUM(C19:C34) -> 4 | D35: =SUM(D19:D34) -> 8 | E35: =SUM(E19:E34) -> 20
A37: 2) 9 давхар барилга (1-9F)
A38: Давхар (блок хүрсэн шат) | B38: Багц-1 | C38: Багц-2 | D38: Багц-3.1 | E38: Багц-3.2 | F38: Багц-3.3 | G38: Багц-4.1 | H38: Багц-4.2 | I38: Нийт блок
A39: Угсралт эхлээгүй | B39: =COUNTIFS($G$69:$G$88,"Эхлээгүй",$C$69:$C$88,9) -> 1 | C39: =COUNTIFS($G$101:$G$126,"Эхлээгүй",$C$101:$C$126,9) -> 0 | D39: =COUNTIFS($G$138:$G$148,"Эхлээгүй",$C$138:$C$148,9) -> 11 | E39: =COUNTIFS($G$163:$G$174,"Эхлээгүй",$C$163:$C$174,9) -> 1 | F39: =COUNTIFS($G$188:$G$201,"Эхлээгүй",$C$188:$C$201,9) -> 2 | G39: =COUNTIFS($G$213:$G$228,"Эхлээгүй",$C$213:$C$228,9) -> 0 | H39: =COUNTIFS($G$241:$G$254,"Эхлээгүй",$C$241:$C$254,9) -> 1 | I39: =SUM(B39:H39) -> 16
A40: Зөвхөн зоорь/суурь (давхар цутгалт эхлээгүй) | B40: =COUNTIFS($G$69:$G$88,"Зоорь*",$C$69:$C$88,9)+COUNTIFS($G$69:$G$88,"Зөвхөн*",$C$69:$C$88,9) -> 0 | C40: =COUNTIFS($G$101:$G$126,"Зоорь*",$C$101:$C$126,9)+COUNTIFS($G$101:$G$126,"Зөвхөн*",$C$101:$C$126,9) -> 0 | D40: =COUNTIFS($G$138:$G$148,"Зоорь*",$C$138:$C$148,9)+COUNTIFS($G$138:$G$148,"Зөвхөн*",$C$138:$C$148,9) -> 0 | E40: =COUNTIFS($G$163:$G$174,"Зоорь*",$C$163:$C$174,9)+COUNTIFS($G$163:$G$174,"Зөвхөн*",$C$163:$C$174,9) -> 0 | F40: =COUNTIFS($G$188:$G$201,"Зоорь*",$C$188:$C$201,9)+COUNTIFS($G$188:$G$201,"Зөвхөн*",$C$188:$C$201,9) -> 0 | G40: =COUNTIFS($G$213:$G$228,"Зоорь*",$C$213:$C$228,9)+COUNTIFS($G$213:$G$228,"Зөвхөн*",$C$213:$C$228,9) -> 0 | H40: =COUNTIFS($G$241:$G$254,"Зоорь*",$C$241:$C$254,9)+COUNTIFS($G$241:$G$254,"Зөвхөн*",$C$241:$C$254,9) -> 0 | I40: =SUM(B40:H40) -> 0
A41: 1F-д явж байгаа | B41: =COUNTIFS($D$69:$D$88,1,$F$69:$F$88,"Хийгдээгүй",$C$69:$C$88,9) -> 1 | C41: =COUNTIFS($D$101:$D$126,1,$F$101:$F$126,"Хийгдээгүй",$C$101:$C$126,9) -> 0 | D41: =COUNTIFS($D$138:$D$148,1,$F$138:$F$148,"Хийгдээгүй",$C$138:$C$148,9) -> 0 | E41: =COUNTIFS($D$163:$D$174,1,$F$163:$F$174,"Хийгдээгүй",$C$163:$C$174,9) -> 0 | F41: =COUNTIFS($D$188:$D$201,1,$F$188:$F$201,"Хийгдээгүй",$C$188:$C$201,9) -> 0 | G41: =COUNTIFS($D$213:$D$228,1,$F$213:$F$228,"Хийгдээгүй",$C$213:$C$228,9) -> 0 | H41: =COUNTIFS($D$241:$D$254,1,$F$241:$F$254,"Хийгдээгүй",$C$241:$C$254,9) -> 0 | I41: =SUM(B41:H41) -> 1
A42: 2F-д явж байгаа | B42: =COUNTIFS($D$69:$D$88,2,$F$69:$F$88,"Хийгдээгүй",$C$69:$C$88,9) -> 0 | C42: =COUNTIFS($D$101:$D$126,2,$F$101:$F$126,"Хийгдээгүй",$C$101:$C$126,9) -> 0 | D42: =COUNTIFS($D$138:$D$148,2,$F$138:$F$148,"Хийгдээгүй",$C$138:$C$148,9) -> 0 | E42: =COUNTIFS($D$163:$D$174,2,$F$163:$F$174,"Хийгдээгүй",$C$163:$C$174,9) -> 0 | F42: =COUNTIFS($D$188:$D$201,2,$F$188:$F$201,"Хийгдээгүй",$C$188:$C$201,9) -> 0 | G42: =COUNTIFS($D$213:$D$228,2,$F$213:$F$228,"Хийгдээгүй",$C$213:$C$228,9) -> 0 | H42: =COUNTIFS($D$241:$D$254,2,$F$241:$F$254,"Хийгдээгүй",$C$241:$C$254,9) -> 0 | I42: =SUM(B42:H42) -> 0
A43: 3F-д явж байгаа | B43: =COUNTIFS($D$69:$D$88,3,$F$69:$F$88,"Хийгдээгүй",$C$69:$C$88,9) -> 0 | C43: =COUNTIFS($D$101:$D$126,3,$F$101:$F$126,"Хийгдээгүй",$C$101:$C$126,9) -> 0 | D43: =COUNTIFS($D$138:$D$148,3,$F$138:$F$148,"Хийгдээгүй",$C$138:$C$148,9) -> 0 | E43: =COUNTIFS($D$163:$D$174,3,$F$163:$F$174,"Хийгдээгүй",$C$163:$C$174,9) -> 0 | F43: =COUNTIFS($D$188:$D$201,3,$F$188:$F$201,"Хийгдээгүй",$C$188:$C$201,9) -> 0 | G43: =COUNTIFS($D$213:$D$228,3,$F$213:$F$228,"Хийгдээгүй",$C$213:$C$228,9) -> 0 | H43: =COUNTIFS($D$241:$D$254,3,$F$241:$F$254,"Хийгдээгүй",$C$241:$C$254,9) -> 0 | I43: =SUM(B43:H43) -> 0
...

Sheet Sheet1
C3: 45874 | D3: 46157 | E3: =+D3-C3 -> 283
D4: 46147 | E4: =+D4-C3 -> 273
E5: =+E4/E3 -> 0.96466431

Sheet БАГЦ-1 2025-12-31
A2: БАГЦ 1 БАРИЛГА УГСРАЛТЫН ГҮЙЦЭТГЭЛ
E3: Байгууллага | G3: "Сэлбэ хорин минутын хот корпорац"ХХК | L3: Шифр
E4: Харьяалах газар | G4: БАГЦ-1 | L4: Хувилбар, №
E5: Баримт бичгийн нэр | G5: Талбайн мэдээлэл | L5: Батлагдсан огноо
